Workbook

Sheet 公式
E2: l(y,x)=not(l(y-1,x-1) xor l(y-1,x) xor l(y-1,x+1) xor l(y-2,x)); | K2: p=B(n)*F | M2: b,f,e,l → p = b(n)*f
B3: F=K^T^-1 | E3: b(y,x)=b(y-1,x-1) xor b(y-1,x) xor b(y-1,x+1) xor b(y-2,x) | K3: q=rev(F(n), p) | M3: p,f(n) → q = rev(f(n), p)
B4: F^-1=K^T | E4: f(y,x)=f(y-1,x-1) xor f(y-2,x) | K4: y=L(n) | M4: q,l(n) → z = Q(S)*l(n)
B5: F^T=K^-1 | E5: g(y,x)=g(y-1,x-1) xor g(y-2,x) xor g(y-1,x) | K5: z=q(H)*y | M5: p,f(n) → g = gcd(p,f(n))
E6: e(y,x)=e(y-1,x-1) xor e(y-1,x+1) | K6: g=gcd(p,F(n)) | M6: g,e → h = g*e
B7: K*P=A | E7: h(y,x):=h(y-1,x-1) xor h(y-1,x+1) xor h(y-2,x) | K7: H(0)=g*E | M7: h → r = fxrst1(h)
B8: K^-1*A=F^T*A=P | K8: x=H^-1*z | M8: h,z,r → x 满足 h*x=z
K9: T(0)=x | M9: x → t(0)=x
M10: t → GeneMat(t)
B11: 扩散多项式逆法
B13: p=af
B14: h=f(n)
B16: p*q=1 mod h，求q
B17: Z=q*Y，Y已知求Z
B19: g=gcd(p,h)，g=1如果可逆
B20: Z=g*X，Z已知求X
B21: s=g^-1，X=g^-1*Z=s*Z

Sheet B
A1: n
B2: 1 | C2: 0 | D2: 0 | E2: 0 | F2: 0 | G2: 0 | H2: 0 | I2: 0 | J2: 0 | K2: 0 | L2: 0 | M2: 0 | N2: 0 | O2: 0 | P2: 0 | Q2: 0 | R2: 0 | S2: 0 | T2: 0 | U2: 0 | V2: 0 | W2: 0 | X2: 0 | Y2: 0 | Z2: 0 | AA2: 0 | AB2: 0 | AC2: 0 | AD2: 0 | AE2: 0 | AF2: 0 | AG2: 0
B3: =MOD(A2+B2+C2+B1,2) -> 1 | C3: =MOD(B2+C2+D2+C1,2) -> 1 | D3: =MOD(C2+D2+E2+D1,2) -> 0 | E3: =MOD(D2+E2+F2+E1,2) -> 0 | F3: =MOD(E2+F2+G2+F1,2) -> 0 | G3: =MOD(F2+G2+H2+G1,2) -> 0 | H3: =MOD(G2+H2+I2+H1,2) -> 0 | I3: =MOD(H2+I2+J2+I1,2) -> 0 | ... AG3: =MOD(AF2+AG2+AH2+AG1,2) -> 0
B4: =MOD(A3+B3+C3+B2,2) -> 1 | C4: =MOD(B3+C3+D3+C2,2) -> 0 | D4: =MOD(C3+D3+E3+D2,2) -> 1 | E4: =MOD(D3+E3+F3+E2,2) -> 0 | F4: =MOD(E3+F3+G3+F2,2) -> 0 | G4: =MOD(F3+G3+H3+G2,2) -> 0 | H4: =MOD(G3+H3+I3+H2,2) -> 0 | I4: =MOD(H3+I3+J3+I2,2) -> 0 | ... AG4: =MOD(AF3+AG3+AH3+AG2,2) -> 0
B5: =MOD(A4+B4+C4+B3,2) -> 0 | C5: =MOD(B4+C4+D4+C3,2) -> 1 | D5: =MOD(C4+D4+E4+D3,2) -> 1 | E5: =MOD(D4+E4+F4+E3,2) -> 1 | F5: =MOD(E4+F4+G4+F3,2) -> 0 | G5: =MOD(F4+G4+H4+G3,2) -> 0 | H5: =MOD(G4+H4+I4+H3,2) -> 0 | I5: =MOD(H4+I4+J4+I3,2) -> 0 | ... AG5: =MOD(AF4+AG4+AH4+AG3,2) -> 0
B6: =MOD(A5+B5+C5+B4,2) -> 0 | C6: =MOD(B5+C5+D5+C4,2) -> 0 | D6: =MOD(C5+D5+E5+D4,2) -> 0 | E6: =MOD(D5+E5+F5+E4,2) -> 0 | F6: =MOD(E5+F5+G5+F4,2) -> 1 | G6: =MOD(F5+G5+H5+G4,2) -> 0 | H6: =MOD(G5+H5+I5+H4,2) -> 0 | I6: =MOD(H5+I5+J5+I4,2) -> 0 | ... AG6: =MOD(AF5+AG5+AH5+AG4,2) -> 0
B7: =MOD(A6+B6+C6+B5,2) -> 0 | C7: =MOD(B6+C6+D6+C5,2) -> 1 | D7: =MOD(C6+D6+E6+D5,2) -> 1 | E7: =MOD(D6+E6+F6+E5,2) -> 0 | F7: =MOD(E6+F6+G6+F5,2) -> 1 | G7: =MOD(F6+G6+H6+G5,2) -> 1 | H7: =MOD(G6+H6+I6+H5,2) -> 0 | I7: =MOD(H6+I6+J6+I5,2) -> 0 | ... AG7: =MOD(AF6+AG6+AH6+AG5,2) -> 0
B8: =MOD(A7+B7+C7+B6,2) -> 1 | C8: =MOD(B7+C7+D7+C6,2) -> 0 | D8: =MOD(C7+D7+E7+D6,2) -> 0 | E8: =MOD(D7+E7+F7+E6,2) -> 0 | F8: =MOD(E7+F7+G7+F6,2) -> 1 | G8: =MOD(F7+G7+H7+G6,2) -> 0 | H8: =MOD(G7+H7+I7+H6,2) -> 1 | I8: =MOD(H7+I7+J7+I6,2) -> 0 | ... AG8: =MOD(AF7+AG7+AH7+AG6,2) -> 0
B9: =MOD(A8+B8+C8+B7,2) -> 1 | C9: =MOD(B8+C8+D8+C7,2) -> 0 | D9: =MOD(C8+D8+E8+D7,2) -> 1 | E9: =MOD(D8+E8+F8+E7,2) -> 1 | F9: =MOD(E8+F8+G8+F7,2) -> 0 | G9: =MOD(F8+G8+H8+G7,2) -> 1 | H9: =MOD(G8+H8+I8+H7,2) -> 1 | I9: =MOD(H8+I8+J8+I7,2) -> 1 | ... AG9: =MOD(AF8+AG8+AH8+AG7,2) -> 0
B10: =MOD(A9+B9+C9+B8,2) -> 0 | C10: =MOD(B9+C9+D9+C8,2) -> 0 | D10: =MOD(C9+D9+E9+D8,2) -> 0 | E10: =MOD(D9+E9+F9+E8,2) -> 0 | F10: =MOD(E9+F9+G9+F8,2) -> 1 | G10: =MOD(F9+G9+H9+G8,2) -> 0 | H10: =MOD(G9+H9+I9+H8,2) -> 0 | I10: =MOD(H9+I9+J9+I8,2) -> 0 | ... AG10: =MOD(AF9+AG9+AH9+AG8,2) -> 0
B11: =MOD(A10+B10+C10+B9,2) -> 1 | C11: =MOD(B10+C10+D10+C9,2) -> 0 | D11: =MOD(C10+D10+E10+D9,2) -> 1 | E11: =MOD(D10+E10+F10+E9,2) -> 0 | F11: =MOD(E10+F10+G10+F9,2) -> 1 | G11: =MOD(F10+G10+H10+G9,2) -> 0 | H11: =MOD(G10+H10+I10+H9,2) -> 1 | I11: =MOD(H10+I10+J10+I9,2) -> 0 | ... AG11: =MOD(AF10+AG10+AH10+AG9,2) -> 0
B12: =MOD(A11+B11+C11+B10,2) -> 1 | C12: =MOD(B11+C11+D11+C10,2) -> 0 | D12: =MOD(C11+D11+E11+D10,2) -> 1 | E12: =MOD(D11+E11+F11+E10,2) -> 0 | F12: =MOD(E11+F11+G11+F10,2) -> 0 | G12: =MOD(F11+G11+H11+G10,2) -> 0 | H12: =MOD(G11+H11+I11+H10,2) -> 1 | I12: =MOD(H11+I11+J11+I10,2) -> 0 | ... AG12: =MOD(AF11+AG11+AH11+AG10,2) -> 0
B13: =MOD(A12+B12+C12+B11,2) -> 0 | C13: =MOD(B12+C12+D12+C11,2) -> 0 | D13: =MOD(C12+D12+E12+D11,2) -> 0 | E13: =MOD(D12+E12+F12+E11,2) -> 1 | F13: =MOD(E12+F12+G12+F11,2) -> 1 | G13: =MOD(F12+G12+H12+G11,2) -> 1 | H13: =MOD(G12+H12+I12+H11,2) -> 0 | I13: =MOD(H12+I12+J12+I11,2) -> 0 | ... AG13: =MOD(AF12+AG12+AH12+AG11,2) -> 0
B14: =MOD(A13+B13+C13+B12,2) -> 1 | C14: =MOD(B13+C13+D13+C12,2) -> 0 | D14: =MOD(C13+D13+E13+D12,2) -> 0 | E14: =MOD(D13+E13+F13+E12,2) -> 0 | F14: =MOD(E13+F13+G13+F12,2) -> 1 | G14: =MOD(F13+G13+H13+G12,2) -> 0 | H14: =MOD(G13+H13+I13+H12,2) -> 0 | I14: =MOD(H13+I13+J13+I12,2) -> 0 | ... AG14: =MOD(AF13+AG13+AH13+AG12,2) -> 0
... B33: =MOD(A32+B32+C32+B31,2) -> 1 | C33: =MOD(B32+C32+D32+C31,2) -> 0 | D33: =MOD(C32+D32+E32+D31,2) -> 1 | E33: =MOD(D32+E32+F32+E31,2) -> 1 | F33: =MOD(E32+F32+G32+F31,2) -> 0 | G33: =MOD(F32+G32+H32+G31,2) -> 1 | H33: =MOD(G32+H32+I32+H31,2) -> 1 | I33: =MOD(H32+I32+J32+I31,2) -> 0 | ... AG33: =MOD(AF32+AG32+AH32+AG31,2) -> 1

Sheet Y(灯)
B1: n-1
C3: 1 | Y3: 0 | AA3: 0 | AB3: 0 | AD3: 0 | AE3: 0 | AF3: 0 | AH3: 0 | AI3: 0 | AJ3: 0 | AK3: 0 | AM3: 0 | AN3: 0 | AO3: 0 | AP3: 0 | AQ3: 0 | AS3: 0 | AT3: 0 | AU3: 0 | AV3: 0 | AW3: 0 | AX3: 0 | AZ3: 0 | BA3: 0 | BB3: 0 | BC3: 0 | BD3: 0 | BE3: 0 | BF3: 0 | BH3: 0 | BI3: 0 | BJ3: 0 | BK3: 0 | BL3: 0 | BM3: 0 | BN3: 0 | BO3: 0 | BQ3: 0 | BR3: 0 | BS3: 0 | BT3: 0 | BU3: 0 | BV3: 0 | BW3: 0 | BX3: 0 | BY3: 0
C4: =MOD(A3+B3+C3+A2+'Y(递推)'!A3+'Y(递推)'!B3+'Y(递推)'!C3+'Y(递推)'!A2+'Y(递推)'!B2+1,2) -> 1 | D4: =MOD(B3+C3+D3+B2+'Y(递推)'!B3+'Y(递推)'!C3+'Y(递推)'!D3+'Y(递推)'!B2+'Y(递推)'!C2+1,2) -> 1 | Y4: =MOD(X3+Y3+Z3+Y2+1,2) -> 1 | AA4: =MOD(Z3+AA3+AB3+AA2+1,2) -> 1 | AB4: =MOD(AA3+AB3+AC3+AB2+1,2) -> 1 | AD4: =MOD(AC3+AD3+AE3+AD2+1,2) -> 1 | AE4: =MOD(AD3+AE3+AF3+AE2+1,2) -> 1 | AF4: =MOD(AE3+AF3+AG3+AF2+1,2) -> 1 | AH4: =MOD(AG3+AH3+AI3+AH2+1,2) -> 1 | AI4: =MOD(AH3+AI3+AJ3+AI2+1,2) -> 1 | AJ4: =MOD(AI3+AJ3+AK3+AJ2+1,2) -> 1 | AK4: =MOD(AJ3+AK3+AL3+AK2+1,2) -> 1 | AM4: =MOD(AL3+AM3+AN3+AM2+1,2) -> 1 | AN4: =MOD(AM3+AN3+AO3+AN2+1,2) -> 1 | AO4: =MOD(AN3+AO3+AP3+AO2+1,2) -> 1 | AP4: =MOD(AO3+AP3+AQ3+AP2+1,2) -> 1 | AQ4: =MOD(AP3+AQ3+AR3+AQ2+1,2) -> 1 | AS4: =MOD(AR3+AS3+AT3+AS2+1,2) -> 1 | AT4: =MOD(AS3+AT3+AU3+AT2+1,2) -> 1 | AU4: =MOD(AT3+AU3+AV3+AU2+1,2) -> 1 | AV4: =MOD(AU3+AV3+AW3+AV2+1,2) -> 1 | AW4: =MOD(AV3+AW3+AX3+AW2+1,2) -> 1 | AX4: =MOD(AW3+AX3+AY3+AX2+1,2) -> 1 | AZ4: =MOD(AY3+AZ3+BA3+AZ2+1,2) -> 1 | BA4: =MOD(AZ3+BA3+BB3+BA2+1,2) -> 1 | BB4: =MOD(BA3+BB3+BC3+BB2+1,2) -> 1 | BC4: =MOD(BB3+BC3+BD3+BC2+1,2) -> 1 | BD4: =MOD(BC3+BD3+BE3+BD2+1,2) -> 1 | BE4: =MOD(BD3+BE3+BF3+BE2+1,2) -> 1 | BF4: =MOD(BE3+BF3+BG3+BF2+1,2) -> 1 | BH4: =MOD(BG3+BH3+BI3+BH2+1,2) -> 1 | BI4: =MOD(BH3+BI3+BJ3+BI2+1,2) -> 1 | BJ4: =MOD(BI3+BJ3+BK3+BJ2+1,2) -> 1 | BK4: =MOD(BJ3+BK3+BL3+BK2+1,2) -> 1 | BL4: =MOD(BK3+BL3+BM3+BL2+1,2) -> 1 | BM4: =MOD(BL3+BM3+BN3+BM2+1,2) -> 1 | BN4: =MOD(BM3+BN3+BO3+BN2+1,2) -> 1 | BO4: =MOD(BN3+BO3+BP3+BO2+1,2) -> 1 | BQ4: =MOD(BP3+BQ3+BR3+BQ2+1,2) -> 1 | BR4: =MOD(BQ3+BR3+BS3+BR2+1,2) -> 1 | BS4: =MOD(BR3+BS3+BT3+BS2+1,2) -> 1 | BT4: =MOD(BS3+BT3+BU3+BT2+1,2) -> 1 | BU4: =MOD(BT3+BU3+BV3+BU2+1,2) -> 1 | BV4: =MOD(BU3+BV3+BW3+BV2+1,2) -> 1 | BW4: =MOD(BV3+BW3+BX3+BW2+1,2) -> 1 | BX4: =MOD(BW3+BX3+BY3+BX2+1,2) -> 1 | BY4: =MOD(BX3+BY3+BZ3+BY2+1,2) -> 1
C5: =MOD(A4+B4+C4+A3+'Y(递推)'!A4+'Y(递推)'!B4+'Y(递推)'!C4+'Y(递推)'!A3+'Y(递推)'!B3+1,2) -> 1 | D5: =MOD(B4+C4+D4+B3+'Y(递推)'!B4+'Y(递推)'!C4+'Y(递推)'!D4+'Y(递推)'!B3+'Y(递推)'!C3+1,2) -> 0 | E5: =MOD(C4+D4+E4+C3+'Y(递推)'!C4+'Y(递推)'!D4+'Y(递推)'!E4+'Y(递推)'!C3+'Y(递推)'!D3+1,2) -> 1 | AA5: =MOD(Z4+AA4+AB4+AA3+1,2) -> 1 | AB5: =MOD(AA4+AB4+AC4+AB3+1,2) -> 1 | AD5: =MOD(AC4+AD4+AE4+AD3+1,2) -> 1 | AE5: =MOD(AD4+AE4+AF4+AE3+1,2) -> 0 | AF5: =MOD(AE4+AF4+AG4+AF3+1,2) -> 1 | AH5: =MOD(AG4+AH4+AI4+AH3+1,2) -> 1 | AI5: =MOD(AH4+AI4+AJ4+AI3+1,2) -> 0 | AJ5: =MOD(AI4+AJ4+AK4+AJ3+1,2) -> 0 | AK5: =MOD(AJ4+AK4+AL4+AK3+1,2) -> 1 | AM5: =MOD(AL4+AM4+AN4+AM3+1,2) -> 1 | AN5: =MOD(AM4+AN4+AO4+AN3+1,2) -> 0 | AO5: =MOD(AN4+AO4+AP4+AO3+1,2) -> 0 | AP5: =MOD(AO4+AP4+AQ4+AP3+1,2) -> 0 | AQ5: =MOD(AP4+AQ4+AR4+AQ3+1,2) -> 1 | AS5: =MOD(AR4+AS4+AT4+AS3+1,2) -> 1 | AT5: =MOD(AS4+AT4+AU4+AT3+1,2) -> 0 | AU5: =MOD(AT4+AU4+AV4+AU3+1,2) -> 0 | AV5: =MOD(AU4+AV4+AW4+AV3+1,2) -> 0 | AW5: =MOD(AV4+AW4+AX4+AW3+1,2) -> 0 | AX5: =MOD(AW4+AX4+AY4+AX3+1,2) -> 1 | AZ5: =MOD(AY4+AZ4+BA4+AZ3+1,2) -> 1 | BA5: =MOD(AZ4+BA4+BB4+BA3+1,2) -> 0 | BB5: =MOD(BA4+BB4+BC4+BB3+1,2) -> 0 | BC5: =MOD(BB4+BC4+BD4+BC3+1,2) -> 0 | BD5: =MOD(BC4+BD4+BE4+BD3+1,2) -> 0 | BE5: =MOD(BD4+BE4+BF4+BE3+1,2) -> 0 | BF5: =MOD(BE4+BF4+BG4+BF3+1,2) -> 1 | BH5: =MOD(BG4+BH4+BI4+BH3+1,2) -> 1 | BI5: =MOD(BH4+BI4+BJ4+BI3+1,2) -> 0 | BJ5: =MOD(BI4+BJ4+BK4+BJ3+1,2) -> 0 | BK5: =MOD(BJ4+BK4+BL4+BK3+1,2) -> 0 | BL5: =MOD(BK4+BL4+BM4+BL3+1,2) -> 0 | BM5: =MOD(BL4+BM4+BN4+BM3+1,2) -> 0 | BN5: =MOD(BM4+BN4+BO4+BN3+1,2) -> 0 | BO5: =MOD(BN4+BO4+BP4+BO3+1,2) -> 1 | BQ5: =MOD(BP4+BQ4+BR4+BQ3+1,2) -> 1 | BR5: =MOD(BQ4+BR4+BS4+BR3+1,2) -> 0 | BS5: =MOD(BR4+BS4+BT4+BS3+1,2) -> 0 | BT5: =MOD(BS4+BT4+BU4+BT3+1,2) -> 0 | BU5: =MOD(BT4+BU4+BV4+BU3+1,2) -> 0 | BV5: =MOD(BU4+BV4+BW4+BV3+1,2) -> 0 | BW5: =MOD(BV4+BW4+BX4+BW3+1,2) -> 0 | BX5: =MOD(BW4+BX4+BY4+BX3+1,2) -> 0 | BY5: =MOD(BX4+BY4+BZ4+BY3+1,2) -> 1
C6: =MOD(A5+B5+C5+A4+'Y(递推)'!A5+'Y(递推)'!B5+'Y(递推)'!C5+'Y(递推)'!A4+'Y(递推)'!B4+1,2) -> 0 | D6: =MOD(B5+C5+D5+B4+'Y(递推)'!B5+'Y(递推)'!C5+'Y(递推)'!D5+'Y(递推)'!B4+'Y(递推)'!C4+1,2) -> 0 | E6: =MOD(C5+D5+E5+C4+'Y(递推)'!C5+'Y(递推)'!D5+'Y(递推)'!E5+'Y(递推)'!C4+'Y(递推)'!D4+1,2) -> 0 | F6: =MOD(D5+E5+F5+D4+'Y(递推)'!D5+'Y(递推)'!E5+'Y(递推)'!F5+'Y(递推)'!D4+'Y(递推)'!E4+1,2) -> 0 | AD6: =MOD(AC5+AD5+AE5+AD4+1,2) -> 1 | AE6: =MOD(AD5+AE5+AF5+AE4+1,2) -> 0 | AF6: =MOD(AE5+AF5+AG5+AF4+1,2) -> 1 | AH6: =MOD(AG5+AH5+AI5+AH4+1,2) -> 1 | AI6: =MOD(AH5+AI5+AJ5+AI4+1,2) -> 1 | AJ6: =MOD(AI5+AJ5+AK5+AJ4+1,2) -> 1 | AK6: =MOD(AJ5+AK5+AL5+AK4+1,2) -> 1 | AM6: =MOD(AL5+AM5+AN5+AM4+1,2) -> 1 | AN6: =MOD(AM5+AN5+AO5+AN4+1,2) -> 1 | AO6: =MOD(AN5+AO5+AP5+AO4+1,2) -> 0 | AP6: =MOD(AO5+AP5+AQ5+AP4+1,2) -> 1 | AQ6: =MOD(AP5+AQ5+AR5+AQ4+1,2) -> 1 | AS6: =MOD(AR5+AS5+AT5+AS4+1,2) -> 1 | AT6: =MOD(AS5+AT5+AU5+AT4+1,2) -> 1 | AU6: =MOD(AT5+AU5+AV5+AU4+1,2) -> 0 | AV6: =MOD(AU5+AV5+AW5+AV4+1,2) -> 0 | AW6: =MOD(AV5+AW5+AX5+AW4+1,2) -> 1 | AX6: =MOD(AW5+AX5+AY5+AX4+1,2) -> 1 | AZ6: =MOD(AY5+AZ5+BA5+AZ4+1,2) -> 1 | BA6: =MOD(AZ5+BA5+BB5+BA4+1,2) -> 1 | BB6: =MOD(BA5+BB5+BC5+BB4+1,2) -> 0 | BC6: =MOD(BB5+BC5+BD5+BC4+1,2) -> 0 | BD6: =MOD(BC5+BD5+BE5+BD4+1,2) -> 0 | BE6: =MOD(BD5+BE5+BF5+BE4+1,2) -> 1 | BF6: =MOD(BE5+BF5+BG5+BF4+1,2) -> 1 | BH6: =MOD(BG5+BH5+BI5+BH4+1,2) -> 1 | BI6: =MOD(BH5+BI5+BJ5+BI4+1,2) -> 1 | BJ6: =MOD(BI5+BJ5+BK5+BJ4+1,2) -> 0 | BK6: =MOD(BJ5+BK5+BL5+BK4+1,2) -> 0 | BL6: =MOD(BK5+BL5+BM5+BL4+1,2) -> 0 | BM6: =MOD(BL5+BM5+BN5+BM4+1,2) -> 0 | BN6: =MOD(BM5+BN5+BO5+BN4+1,2) -> 1 | BO6: =MOD(BN5+BO5+BP5+BO4+1,2) -> 1 | BQ6: =MOD(BP5+BQ5+BR5+BQ4+1,2) -> 1 | BR6: =MOD(BQ5+BR5+BS5+BR4+1,2) -> 1 | BS6: =MOD(BR5+BS5+BT5+BS4+1,2) -> 0 | BT6: =MOD(BS5+BT5+BU5+BT4+1,2) -> 0 | BU6: =MOD(BT5+BU5+BV5+BU4+1,2) -> 0 | BV6: =MOD(BU5+BV5+BW5+BV4+1,2) -> 0 | BW6: =MOD(BV5+BW5+BX5+BW4+1,2) -> 0 | BX6: =MOD(BW5+BX5+BY5+BX4+1,2) -> 1 | BY6: =MOD(BX5+BY5+BZ5+BY4+1,2) -> 1
C7: =MOD(A6+B6+C6+A5+'Y(递推)'!A6+'Y(递推)'!B6+'Y(递推)'!C6+'Y(递推)'!A5+'Y(递推)'!B5+1,2) -> 1 | D7: =MOD(B6+C6+D6+B5+'Y(递推)'!B6+'Y(递推)'!C6+'Y(递推)'!D6+'Y(递推)'!B5+'Y(递推)'!C5+1,2) -> 0 | E7: =MOD(C6+D6+E6+C5+'Y(递推)'!C6+'Y(递推)'!D6+'Y(递推)'!E6+'Y(递推)'!C5+'Y(递推)'!D5+1,2) -> 0 | F7: =MOD(D6+E6+F6+D5+'Y(递推)'!D6+'Y(递推)'!E6+'Y(递推)'!F6+'Y(递推)'!D5+'Y(递推)'!E5+1,2) -> 0 | G7: =MOD(E6+F6+G6+E5+'Y(递推)'!E6+'Y(递推)'!F6+'Y(递推)'!G6+'Y(递推)'!E5+'Y(递推)'!F5+1,2) -> 1 | AH7: =MOD(AG6+AH6+AI6+AH5+1,2) -> 0 | AI7: =MOD(AH6+AI6+AJ6+AI5+1,2) -> 0 | AJ7: =MOD(AI6+AJ6+AK6+AJ5+1,2) -> 0 | AK7: =MOD(AJ6+AK6+AL6+AK5+1,2) -> 0 | AM7: =MOD(AL6+AM6+AN6+AM5+1,2) -> 0 | AN7: =MOD(AM6+AN6+AO6+AN5+1,2) -> 1 | AO7: =MOD(AN6+AO6+AP6+AO5+1,2) -> 1 | AP7: =MOD(AO6+AP6+AQ6+AP5+1,2) -> 1 | AQ7: =MOD(AP6+AQ6+AR6+AQ5+1,2) -> 0 | AS7: =MOD(AR6+AS6+AT6+AS5+1,2) -> 0 | AT7: =MOD(AS6+AT6+AU6+AT5+1,2) -> 1 | AU7: =MOD(AT6+AU6+AV6+AU5+1,2) -> 0 | AV7: =MOD(AU6+AV6+AW6+AV5+1,2) -> 0 | AW7: =MOD(AV6+AW6+AX6+AW5+1,2) -> 1 | AX7: =MOD(AW6+AX6+AY6+AX5+1,2) -> 0 | AZ7: =MOD(AY6+AZ6+BA6+AZ5+1,2) -> 0 | BA7: =MOD(AZ6+BA6+BB6+BA5+1,2) -> 1 | BB7: =MOD(BA6+BB6+BC6+BB5+1,2) -> 0 | BC7: =MOD(BB6+BC6+BD6+BC5+1,2) -> 1 | BD7: =MOD(BC6+BD6+BE6+BD5+1,2) -> 0 | BE7: =MOD(BD6+BE6+BF6+BE5+1,2) -> 1 | BF7: =MOD(BE6+BF6+BG6+BF5+1,2) -> 0 | BH7: =MOD(BG6+BH6+BI6+BH5+1,2) -> 0 | BI7: =MOD(BH6+BI6+BJ6+BI5+1,2) -> 1 | BJ7: =MOD(BI6+BJ6+BK6+BJ5+1,2) -> 0 | BK7: =MOD(BJ6+BK6+BL6+BK5+1,2) -> 1 | BL7: =MOD(BK6+BL6+BM6+BL5+1,2) -> 1 | BM7: =MOD(BL6+BM6+BN6+BM5+1,2) -> 0 | BN7: =MOD(BM6+BN6+BO6+BN5+1,2) -> 1 | BO7: =MOD(BN6+BO6+BP6+BO5+1,2) -> 0 | BQ7: =MOD(BP6+BQ6+BR6+BQ5+1,2) -> 0 | BR7: =MOD(BQ6+BR6+BS6+BR5+1,2) -> 1 | BS7: =MOD(BR6+BS6+BT6+BS5+1,2) -> 0 | BT7: =MOD(BS6+BT6+BU6+BT5+1,2) -> 1 | BU7: =MOD(BT6+BU6+BV6+BU5+1,2) -> 1 | BV7: =MOD(BU6+BV6+BW6+BV5+1,2) -> 1 | BW7: =MOD(BV6+BW6+BX6+BW5+1,2) -> 0 | BX7: =MOD(BW6+BX6+BY6+BX5+1,2) -> 1 | BY7: =MOD(BX6+BY6+BZ6+BY5+1,2) -> 0
C8: =MOD(A7+B7+C7+A6+'Y(递推)'!A7+'Y(递推)'!B7+'Y(递推)'!C7+'Y(递推)'!A6+'Y(递推)'!B6+1,2) -> 1 | D8: =MOD(B7+C7+D7+B6+'Y(递推)'!B7+'Y(递推)'!C7+'Y(递推)'!D7+'Y(递推)'!B6+'Y(递推)'!C6+1,2) -> 0 | E8: =MOD(C7+D7+E7+C6+'Y(递推)'!C7+'Y(递推)'!D7+'Y(递推)'!E7+'Y(递推)'!C6+'Y(递推)'!D6+1,2) -> 0 | F8: =MOD(D7+E7+F7+D6+'Y(递推)'!D7+'Y(递推)'!E7+'Y(递推)'!F7+'Y(递推)'!D6+'Y(递推)'!E6+1,2) -> 0 | G8: =MOD(E7+F7+G7+E6+'Y(递推)'!E7+'Y(递推)'!F7+'Y(递推)'!G7+'Y(递推)'!E6+'Y(递推)'!F6+1,2) -> 0 | H8: =MOD(F7+G7+H7+F6+'Y(递推)'!F7+'Y(递推)'!G7+'Y(递推)'!H7+'Y(递推)'!F6+'Y(递推)'!G6+1,2) -> 1 | AM8: =MOD(AL7+AM7+AN7+AM6+1,2) -> 1 | AN8: =MOD(AM7+AN7+AO7+AN6+1,2) -> 0 | AO8: =MOD(AN7+AO7+AP7+AO6+1,2) -> 0 | AP8: =MOD(AO7+AP7+AQ7+AP6+1,2) -> 0 | AQ8: =MOD(AP7+AQ7+AR7+AQ6+1,2) -> 1 | AS8: =MOD(AR7+AS7+AT7+AS6+1,2) -> 1 | AT8: =MOD(AS7+AT7+AU7+AT6+1,2) -> 1 | AU8: =MOD(AT7+AU7+AV7+AU6+1,2) -> 0 | AV8: =MOD(AU7+AV7+AW7+AV6+1,2) -> 0 | AW8: =MOD(AV7+AW7+AX7+AW6+1,2) -> 1 | AX8: =MOD(AW7+AX7+AY7+AX6+1,2) -> 1 | AZ8: =MOD(AY7+AZ7+BA7+AZ6+1,2) -> 1 | BA8: =MOD(AZ7+BA7+BB7+BA6+1,2) -> 1 | BB8: =MOD(BA7+BB7+BC7+BB6+1,2) -> 1 | BC8: =MOD(BB7+BC7+BD7+BC6+1,2) -> 0 | BD8: =MOD(BC7+BD7+BE7+BD6+1,2) -> 1 | BE8: =MOD(BD7+BE7+BF7+BE6+1,2) -> 1 | BF8: =MOD(BE7+BF7+BG7+BF6+1,2) -> 1 | BH8: =MOD(BG7+BH7+BI7+BH6+1,2) -> 1 | BI8: =MOD(BH7+BI7+BJ7+BI6+1,2) -> 1 | BJ8: =MOD(BI7+BJ7+BK7+BJ6+1,2) -> 1 | BK8: =MOD(BJ7+BK7+BL7+BK6+1,2) -> 1 | BL8: =MOD(BK7+BL7+BM7+BL6+1,2) -> 1 | BM8: =MOD(BL7+BM7+BN7+BM6+1,2) -> 1 | BN8: =MOD(BM7+BN7+BO7+BN6+1,2) -> 1 | BO8: =MOD(BN7+BO7+BP7+BO6+1,2) -> 1 | BQ8: =MOD(BP7+BQ7+BR7+BQ6+1,2) -> 1 | BR8: =MOD(BQ7+BR7+BS7+BR6+1,2) -> 1 | BS8: =MOD(BR7+BS7+BT7+BS6+1,2) -> 1 | BT8: =MOD(BS7+BT7+BU7+BT6+1,2) -> 1 | BU8: =MOD(BT7+BU7+BV7+BU6+1,2) -> 0 | BV8: =MOD(BU7+BV7+BW7+BV6+1,2) -> 1 | BW8: =MOD(BV7+BW7+BX7+BW6+1,2) -> 1 | BX8: =MOD(BW7+BX7+BY7+BX6+1,2) -> 1 | BY8: =MOD(BX7+BY7+BZ7+BY6+1,2) -> 1
C9: =MOD(A8+B8+C8+A7+'Y(递推)'!A8+'Y(递推)'!B8+'Y(递推)'!C8+'Y(递推)'!A7+'Y(递推)'!B7+1,2) -> 0 | D9: =MOD(B8+C8+D8+B7+'Y(递推)'!B8+'Y(递推)'!C8+'Y(递推)'!D8+'Y(递推)'!B7+'Y(递推)'!C7+1,2) -> 1 | E9: =MOD(C8+D8+E8+C7+'Y(递推)'!C8+'Y(递推)'!D8+'Y(递推)'!E8+'Y(递推)'!C7+'Y(递推)'!D7+1,2) -> 0 | F9: =MOD(D8+E8+F8+D7+'Y(递推)'!D8+'Y(递推)'!E8+'Y(递推)'!F8+'Y(递推)'!D7+'Y(递推)'!E7+1,2) -> 1 | G9: =MOD(E8+F8+G8+E7+'Y(递推)'!E8+'Y(递推)'!F8+'Y(递推)'!G8+'Y(递推)'!E7+'Y(递推)'!F7+1,2) -> 0 | H9: =MOD(F8+G8+H8+F7+'Y(递推)'!F8+'Y(递推)'!G8+'Y(递推)'!H8+'Y(递推)'!F7+'Y(递推)'!G7+1,2) -> 1 | I9: =MOD(G8+H8+I8+G7+'Y(递推)'!G8+'Y(递推)'!H8+'Y(递推)'!I8+'Y(递推)'!G7+'Y(递推)'!H7+1,2) -> 0 | AS9: =MOD(AR8+AS8+AT8+AS7+1,2) -> 1 | AT9: =MOD(AS8+AT8+AU8+AT7+1,2) -> 0 | AU9: =MOD(AT8+AU8+AV8+AU7+1,2) -> 0 | AV9: =MOD(AU8+AV8+AW8+AV7+1,2) -> 0 | AW9: =MOD(AV8+AW8+AX8+AW7+1,2) -> 0 | AX9: =MOD(AW8+AX8+AY8+AX7+1,2) -> 1 | AZ9: =MOD(AY8+AZ8+BA8+AZ7+1,2) -> 1 | BA9: =MOD(AZ8+BA8+BB8+BA7+1,2) -> 1 | BB9: =MOD(BA8+BB8+BC8+BB7+1,2) -> 1 | BC9: =MOD(BB8+BC8+BD8+BC7+1,2) -> 0 | BD9: =MOD(BC8+BD8+BE8+BD7+1,2) -> 1 | BE9: =MOD(BD8+BE8+BF8+BE7+1,2) -> 1 | BF9: =MOD(BE8+BF8+BG8+BF7+1,2) -> 1 | BH9: =MOD(BG8+BH8+BI8+BH7+1,2) -> 1 | BI9: =MOD(BH8+BI8+BJ8+BI7+1,2) -> 1 | BJ9: =MOD(BI8+BJ8+BK8+BJ7+1,2) -> 0 | BK9: =MOD(BJ8+BK8+BL8+BK7+1,2) -> 1 | BL9: =MOD(BK8+BL8+BM8+BL7+1,2) -> 1 | BM9: =MOD(BL8+BM8+BN8+BM7+1,2) -> 0 | BN9: =MOD(BM8+BN8+BO8+BN7+1,2) -> 1 | BO9: =MOD(BN8+BO8+BP8+BO7+1,2) -> 1 | BQ9: =MOD(BP8+BQ8+BR8+BQ7+1,2) -> 1 | BR9: =MOD(BQ8+BR8+BS8+BR7+1,2) -> 1 | BS9: =MOD(BR8+BS8+BT8+BS7+1,2) -> 0 | BT9: =MOD(BS8+BT8+BU8+BT7+1,2) -> 0 | BU9: =MOD(BT8+BU8+BV8+BU7+1,2) -> 0 | BV9: =MOD(BU8+BV8+BW8+BV7+1,2) -> 0 | BW9: =MOD(BV8+BW8+BX8+BW7+1,2) -> 0 | BX9: =MOD(BW8+BX8+BY8+BX7+1,2) -> 1 | BY9: =MOD(BX8+BY8+BZ8+BY7+1,2) -> 1
C10: =MOD(A9+B9+C9+A8+'Y(递推)'!A9+'Y(递推)'!B9+'Y(递推)'!C9+'Y(递推)'!A8+'Y(递推)'!B8+1,2) -> 0 | D10: =MOD(B9+C9+D9+B8+'Y(递推)'!B9+'Y(递推)'!C9+'Y(递推)'!D9+'Y(递推)'!B8+'Y(递推)'!C8+1,2) -> 0 | E10: =MOD(C9+D9+E9+C8+'Y(递推)'!C9+'Y(递推)'!D9+'Y(递推)'!E9+'Y(递推)'!C8+'Y(递推)'!D8+1,2) -> 1 | F10: =MOD(D9+E9+F9+D8+'Y(递推)'!D9+'Y(递推)'!E9+'Y(递推)'!F9+'Y(递推)'!D8+'Y(递推)'!E8+1,2) -> 0 | G10: =MOD(E9+F9+G9+E8+'Y(递推)'!E9+'Y(递推)'!F9+'Y(递推)'!G9+'Y(递推)'!E8+'Y(递推)'!F8+1,2) -> 0 | H10: =MOD(F9+G9+H9+F8+'Y(递推)'!F9+'Y(递推)'!G9+'Y(递推)'!H9+'Y(递推)'!F8+'Y(递推)'!G8+1,2) -> 1 | I10: =MOD(G9+H9+I9+G8+'Y(递推)'!G9+'Y(递推)'!H9+'Y(递推)'!I9+'Y(递推)'!G8+'Y(递推)'!H8+1,2) -> 0 | J10: =MOD(H9+I9+J9+H8+'Y(递推)'!H9+'Y(递推)'!I9+'Y(递推)'!J9+'Y(递推)'!H8+'Y(递推)'!I8+1,2) -> 0 | AZ10: =MOD(AY9+AZ9+BA9+AZ8+1,2) -> 0 | BA10: =MOD(AZ9+BA9+BB9+BA8+1,2) -> 1 | BB10: =MOD(BA9+BB9+BC9+BB8+1,2) -> 0 | BC10: =MOD(BB9+BC9+BD9+BC8+1,2) -> 1 | BD10: =MOD(BC9+BD9+BE9+BD8+1,2) -> 0 | BE10: =MOD(BD9+BE9+BF9+BE8+1,2) -> 1 | BF10: =MOD(BE9+BF9+BG9+BF8+1,2) -> 0 | BH10: =MOD(BG9+BH9+BI9+BH8+1,2) -> 0 | BI10: =MOD(BH9+BI9+BJ9+BI8+1,2) -> 0 | BJ10: =MOD(BI9+BJ9+BK9+BJ8+1,2) -> 0 | BK10: =MOD(BJ9+BK9+BL9+BK8+1,2) -> 0 | BL10: =MOD(BK9+BL9+BM9+BL8+1,2) -> 0 | BM10: =MOD(BL9+BM9+BN9+BM8+1,2) -> 0 | BN10: =MOD(BM9+BN9+BO9+BN8+1,2) -> 0 | BO10: =MOD(BN9+BO9+BP9+BO8+1,2) -> 0 | BQ10: =MOD(BP9+BQ9+BR9+BQ8+1,2) -> 0 | BR10: =MOD(BQ9+BR9+BS9+BR8+1,2) -> 0 | BS10: =MOD(BR9+BS9+BT9+BS8+1,2) -> 1 | BT10: =MOD(BS9+BT9+BU9+BT8+1,2) -> 0 | BU10: =MOD(BT9+BU9+BV9+BU8+1,2) -> 1 | BV10: =MOD(BU9+BV9+BW9+BV8+1,2) -> 0 | BW10: =MOD(BV9+BW9+BX9+BW8+1,2) -> 1 | BX10: =MOD(BW9+BX9+BY9+BX8+1,2) -> 0 | BY10: =MOD(BX9+BY9+BZ9+BY8+1,2) -> 0
C11: =MOD(A10+B10+C10+A9+'Y(递推)'!A10+'Y(递推)'!B10+'Y(递推)'!C10+'Y(递推)'!A9+'Y(递推)'!B9+1,2) -> 0 | D11: =MOD(B10+C10+D10+B9+'Y(递推)'!B10+'Y(递推)'!C10+'Y(递推)'!D10+'Y(递推)'!B9+'Y(递推)'!C9+1,2) -> 0 | E11: =MOD(C10+D10+E10+C9+'Y(递推)'!C10+'Y(递推)'!D10+'Y(递推)'!E10+'Y(递推)'!C9+'Y(递推)'!D9+1,2) -> 0 | F11: =MOD(D10+E10+F10+D9+'Y(递推)'!D10+'Y(递推)'!E10+'Y(递推)'!F10+'Y(递推)'!D9+'Y(递推)'!E9+1,2) -> 0 | G11: =MOD(E10+F10+G10+E9+'Y(递推)'!E10+'Y(递推)'!F10+'Y(递推)'!G10+'Y(递推)'!E9+'Y(递推)'!F9+1,2) -> 0 | H11: =MOD(F10+G10+H10+F9+'Y(递推)'!F10+'Y(递推)'!G10+'Y(递推)'!H10+'Y(递推)'!F9+'Y(递推)'!G9+1,2) -> 0 | I11: =MOD(G10+H10+I10+G9+'Y(递推)'!G10+'Y(递推)'!H10+'Y(递推)'!I10+'Y(递推)'!G9+'Y(递推)'!H9+1,2) -> 0 | J11: =MOD(H10+I10+J10+H9+'Y(递推)'!H10+'Y(递推)'!I10+'Y(递推)'!J10+'Y(递推)'!H9+'Y(递推)'!I9+1,2) -> 0 | K11: =MOD(I10+J10+K10+I9+'Y(递推)'!I10+'Y(递推)'!J10+'Y(递推)'!K10+'Y(递推)'!I9+'Y(递推)'!J9+1,2) -> 0 | BH11: =MOD(BG10+BH10+BI10+BH9+1,2) -> 0 | BI11: =MOD(BH10+BI10+BJ10+BI9+1,2) -> 0 | BJ11: =MOD(BI10+BJ10+BK10+BJ9+1,2) -> 1 | BK11: =MOD(BJ10+BK10+BL10+BK9+1,2) -> 0 | BL11: =MOD(BK10+BL10+BM10+BL9+1,2) -> 0 | BM11: =MOD(BL10+BM10+BN10+BM9+1,2) -> 1 | BN11: =MOD(BM10+BN10+BO10+BN9+1,2) -> 0 | BO11: =MOD(BN10+BO10+BP10+BO9+1,2) -> 0 | BQ11: =MOD(BP10+BQ10+BR10+BQ9+1,2) -> 0 | BR11: =MOD(BQ10+BR10+BS10+BR9+1,2) -> 1 | BS11: =MOD(BR10+BS10+BT10+BS9+1,2) -> 0 | BT11: =MOD(BS10+BT10+BU10+BT9+1,2) -> 1 | BU11: =MOD(BT10+BU10+BV10+BU9+1,2) -> 0 | BV11: =MOD(BU10+BV10+BW10+BV9+1,2) -> 1 | BW11: =MOD(BV10+BW10+BX10+BW9+1,2) -> 0 | BX11: =MOD(BW10+BX10+BY10+BX9+1,2) -> 1 | BY11: =MOD(BX10+BY10+BZ10+BY9+1,2) -> 0
C12: =MOD(A11+B11+C11+A10+'Y(递推)'!A11+'Y(递推)'!B11+'Y(递推)'!C11+'Y(递推)'!A10+'Y(递推)'!B10+1,2) -> 0 | D12: =MOD(B11+C11+D11+B10+'Y(递推)'!B11+'Y(递推)'!C11+'Y(递推)'!D11+'Y(递推)'!B10+'Y(递推)'!C10+1,2) -> 1 | E12: =MOD(C11+D11+E11+C10+'Y(递推)'!C11+'Y(递推)'!D11+'Y(递推)'!E11+'Y(递推)'!C10+'Y(递推)'!D10+1,2) -> 1 | F12: =MOD(D11+E11+F11+D10+'Y(递推)'!D11+'Y(递推)'!E11+'Y(递推)'!F11+'Y(递推)'!D10+'Y(递推)'!E10+1,2) -> 1 | G12: =MOD(E11+F11+G11+E10+'Y(递推)'!E11+'Y(递推)'!F11+'Y(递推)'!G11+'Y(递推)'!E10+'Y(递推)'!F10+1,2) -> 0 | H12: =MOD(F11+G11+H11+F10+'Y(递推)'!F11+'Y(递推)'!G11+'Y(递推)'!H11+'Y(递推)'!F10+'Y(递推)'!G10+1,2) -> 0 | I12: =MOD(G11+H11+I11+G10+'Y(递推)'!G11+'Y(递推)'!H11+'Y(递推)'!I11+'Y(递推)'!G10+'Y(递推)'!H10+1,2) -> 1 | J12: =MOD(H11+I11+J11+H10+'Y(递推)'!H11+'Y(递推)'!I11+'Y(递推)'!J11+'Y(递推)'!H10+'Y(递推)'!I10+1,2) -> 1 | ... L12: =MOD(J11+K11+L11+J10+'Y(递推)'!J11+'Y(递推)'!K11+'Y(递推)'!L11+'Y(递推)'!J10+'Y(递推)'!K10+1,2) -> 0 | BQ12: =MOD(BP11+BQ11+BR11+BQ10+1,2) -> 0 | BR12: =MOD(BQ11+BR11+BS11+BR10+1,2) -> 0 | BS12: =MOD(BR11+BS11+BT11+BS10+1,2) -> 0 | BT12: =MOD(BS11+BT11+BU11+BT10+1,2) -> 0 | BU12: =MOD(BT11+BU11+BV11+BU10+1,2) -> 0 | BV12: =MOD(BU11+BV11+BW11+BV10+1,2) -> 0 | BW12: =MOD(BV11+BW11+BX11+BW10+1,2) -> 0 | BX12: =MOD(BW11+BX11+BY11+BX10+1,2) -> 0 | BY12: =MOD(BX11+BY11+BZ11+BY10+1,2) -> 0
C13: =MOD(A12+B12+C12+A11+'Y(递推)'!A12+'Y(递推)'!B12+'Y(递推)'!C12+'Y(递推)'!A11+'Y(递推)'!B11+1,2) -> 1 | D13: =MOD(B12+C12+D12+B11+'Y(递推)'!B12+'Y(递推)'!C12+'Y(递推)'!D12+'Y(递推)'!B11+'Y(递推)'!C11+1,2) -> 0 | E13: =MOD(C12+D12+E12+C11+'Y(递推)'!C12+'Y(递推)'!D12+'Y(递推)'!E12+'Y(递推)'!C11+'Y(递推)'!D11+1,2) -> 1 | F13: =MOD(D12+E12+F12+D11+'Y(递推)'!D12+'Y(递推)'!E12+'Y(递推)'!F12+'Y(递推)'!D11+'Y(递推)'!E11+1,2) -> 1 | G13: =MOD(E12+F12+G12+E11+'Y(递推)'!E12+'Y(递推)'!F12+'Y(递推)'!G12+'Y(递推)'!E11+'Y(递推)'!F11+1,2) -> 0 | H13: =MOD(F12+G12+H12+F11+'Y(递推)'!F12+'Y(递推)'!G12+'Y(递推)'!H12+'Y(递推)'!F11+'Y(递推)'!G11+1,2) -> 0 | I13: =MOD(G12+H12+I12+G11+'Y(递推)'!G12+'Y(递推)'!H12+'Y(递推)'!I12+'Y(递推)'!G11+'Y(递推)'!H11+1,2) -> 0 | J13: =MOD(H12+I12+J12+H11+'Y(递推)'!H12+'Y(递推)'!I12+'Y(递推)'!J12+'Y(递推)'!H11+'Y(递推)'!I11+1,2) -> 1 | ... M13: =MOD(K12+L12+M12+K11+'Y(递推)'!K12+'Y(递推)'!L12+'Y(递推)'!M12+'Y(递推)'!K11+'Y(递推)'!L11+1,2) -> 1
C14: =MOD(A13+B13+C13+A12+'Y(递推)'!A13+'Y(递推)'!B13+'Y(递推)'!C13+'Y(递推)'!A12+'Y(递推)'!B12+1,2) -> 1 | D14: =MOD(B13+C13+D13+B12+'Y(递推)'!B13+'Y(递推)'!C13+'Y(递推)'!D13+'Y(递推)'!B12+'Y(递推)'!C12+1,2) -> 0 | E14: =MOD(C13+D13+E13+C12+'Y(递推)'!C13+'Y(递推)'!D13+'Y(递推)'!E13+'Y(递推)'!C12+'Y(递推)'!D12+1,2) -> 0 | F14: =MOD(D13+E13+F13+D12+'Y(递推)'!D13+'Y(递推)'!E13+'Y(递推)'!F13+'Y(递推)'!D12+'Y(递推)'!E12+1,2) -> 0 | G14: =MOD(E13+F13+G13+E12+'Y(递推)'!E13+'Y(递推)'!F13+'Y(递推)'!G13+'Y(递推)'!E12+'Y(递推)'!F12+1,2) -> 0 | H14: =MOD(F13+G13+H13+F12+'Y(递推)'!F13+'Y(递推)'!G13+'Y(递推)'!H13+'Y(递推)'!F12+'Y(递推)'!G12+1,2) -> 1 | I14: =MOD(G13+H13+I13+G12+'Y(递推)'!G13+'Y(递推)'!H13+'Y(递推)'!I13+'Y(递推)'!G12+'Y(递推)'!H12+1,2) -> 1 | J14: =MOD(H13+I13+J13+H12+'Y(递推)'!H13+'Y(递推)'!I13+'Y(递推)'!J13+'Y(递推)'!H12+'Y(递推)'!I12+1,2) -> 0 | ... N14: =MOD(L13+M13+N13+L12+'Y(递推)'!L13+'Y(递推)'!M13+'Y(递推)'!N13+'Y(递推)'!L12+'Y(递推)'!M12+1,2) -> 1 | AS14: =MOD(AS4-AL4,2) -> 1 | AT14: =MOD(AT4-AM4,2) -> 0 | AU14: =MOD(AU4-AN4,2) -> 0 | AV14: =MOD(AV4-AO4,2) -> 0 | AW14: =MOD(AW4-AP4,2) -> 0 | AX14: =MOD(AX4-AQ4,2) -> 0
C15: =MOD(A14+B14+C14+A13+'Y(递推)'!A14+'Y(递推)'!B14+'Y(递推)'!C14+'Y(递推)'!A13+'Y(递推)'!B13+1,2) -> 0 | D15: =MOD(B14+C14+D14+B13+'Y(递推)'!B14+'Y(递推)'!C14+'Y(递推)'!D14+'Y(递推)'!B13+'Y(递推)'!C13+1,2) -> 1 | E15: =MOD(C14+D14+E14+C13+'Y(递推)'!C14+'Y(递推)'!D14+'Y(递推)'!E14+'Y(递推)'!C13+'Y(递推)'!D13+1,2) -> 0 | F15: =MOD(D14+E14+F14+D13+'Y(递推)'!D14+'Y(递推)'!E14+'Y(递推)'!F14+'Y(递推)'!D13+'Y(递推)'!E13+1,2) -> 1 | G15: =MOD(E14+F14+G14+E13+'Y(递推)'!E14+'Y(递推)'!F14+'Y(递推)'!G14+'Y(递推)'!E13+'Y(递推)'!F13+1,2) -> 1 | H15: =MOD(F14+G14+H14+F13+'Y(递推)'!F14+'Y(递推)'!G14+'Y(递推)'!H14+'Y(递推)'!F13+'Y(递推)'!G13+1,2) -> 1 | I15: =MOD(G14+H14+I14+G13+'Y(递推)'!G14+'Y(递推)'!H14+'Y(递推)'!I14+'Y(递推)'!G13+'Y(递推)'!H13+1,2) -> 1 | J15: =MOD(H14+I14+J14+H13+'Y(递推)'!H14+'Y(递推)'!I14+'Y(递推)'!J14+'Y(递推)'!H13+'Y(递推)'!I13+1,2) -> 1 | ... O15: =MOD(M14+N14+O14+M13+'Y(递推)'!M14+'Y(递推)'!N14+'Y(递推)'!O14+'Y(递推)'!M13+'Y(递推)'!N13+1,2) -> 0 | AS15: =MOD(AS5-AL5,2) -> 1 | AT15: =MOD(AT5-AM5,2) -> 1 | AU15: =MOD(AU5-AN5,2) -> 0 | AV15: =MOD(AV5-AO5,2) -> 0 | AW15: =MOD(AW5-AP5,2) -> 0 | AX15: =MOD(AX5-AQ5,2) -> 0
C16: =MOD(A15+B15+C15+A14+'Y(递推)'!A15+'Y(递推)'!B15+'Y(递推)'!C15+'Y(递推)'!A14+'Y(递推)'!B14+1,2) -> 0 | D16: =MOD(B15+C15+D15+B14+'Y(递推)'!B15+'Y(递推)'!C15+'Y(递推)'!D15+'Y(递推)'!B14+'Y(递推)'!C14+1,2) -> 0 | E16: =MOD(C15+D15+E15+C14+'Y(递推)'!C15+'Y(递推)'!D15+'Y(递推)'!E15+'Y(递推)'!C14+'Y(递推)'!D14+1,2) -> 0 | F16: =MOD(D15+E15+F15+D14+'Y(递推)'!D15+'Y(递推)'!E15+'Y(递推)'!F15+'Y(递推)'!D14+'Y(递推)'!E14+1,2) -> 1 | G16: =MOD(E15+F15+G15+E14+'Y(递推)'!E15+'Y(递推)'!F15+'Y(递推)'!G15+'Y(递推)'!E14+'Y(递推)'!F14+1,2) -> 0 | H16: =MOD(F15+G15+H15+F14+'Y(递推)'!F15+'Y(递推)'!G15+'Y(递推)'!H15+'Y(递推)'!F14+'Y(递推)'!G14+1,2) -> 1 | I16: =MOD(G15+H15+I15+G14+'Y(递推)'!G15+'Y(递推)'!H15+'Y(递推)'!I15+'Y(递推)'!G14+'Y(递推)'!H14+1,2) -> 0 | J16: =MOD(H15+I15+J15+H14+'Y(递推)'!H15+'Y(递推)'!I15+'Y(递推)'!J15+'Y(递推)'!H14+'Y(递推)'!I14+1,2) -> 0 | ... P16: =MOD(N15+O15+P15+N14+'Y(递推)'!N15+'Y(递推)'!O15+'Y(递推)'!P15+'Y(递推)'!N14+'Y(递推)'!O14+1,2) -> 0 | AS16: =MOD(AS6-AL6,2) -> 1 | AT16: =MOD(AT6-AM6,2) -> 0 | AU16: =MOD(AU6-AN6,2) -> 1 | AV16: =MOD(AV6-AO6,2) -> 0 | AW16: =MOD(AW6-AP6,2) -> 0 | AX16: =MOD(AX6-AQ6,2) -> 0
C17: =MOD(A16+B16+C16+A15+'Y(递推)'!A16+'Y(递推)'!B16+'Y(递推)'!C16+'Y(递推)'!A15+'Y(递推)'!B15+1,2) -> 0 | D17: =MOD(B16+C16+D16+B15+'Y(递推)'!B16+'Y(递推)'!C16+'Y(递推)'!D16+'Y(递推)'!B15+'Y(递推)'!C15+1,2) -> 1 | E17: =MOD(C16+D16+E16+C15+'Y(递推)'!C16+'Y(递推)'!D16+'Y(递推)'!E16+'Y(递推)'!C15+'Y(递推)'!D15+1,2) -> 1 | F17: =MOD(D16+E16+F16+D15+'Y(递推)'!D16+'Y(递推)'!E16+'Y(递推)'!F16+'Y(递推)'!D15+'Y(递推)'!E15+1,2) -> 1 | G17: =MOD(E16+F16+G16+E15+'Y(递推)'!E16+'Y(递推)'!F16+'Y(递推)'!G16+'Y(递推)'!E15+'Y(递推)'!F15+1,2) -> 1 | H17: =MOD(F16+G16+H16+F15+'Y(递推)'!F16+'Y(递推)'!G16+'Y(递推)'!H16+'Y(递推)'!F15+'Y(递推)'!G15+1,2) -> 0 | I17: =MOD(G16+H16+I16+G15+'Y(递推)'!G16+'Y(递推)'!H16+'Y(递推)'!I16+'Y(递推)'!G15+'Y(递推)'!H15+1,2) -> 1 | J17: =MOD(H16+I16+J16+H15+'Y(递推)'!H16+'Y(递推)'!I16+'Y(递推)'!J16+'Y(递推)'!H15+'Y(递推)'!I15+1,2) -> 0 | ... Q17: =MOD(O16+P16+Q16+O15+'Y(递推)'!O16+'Y(递推)'!P16+'Y(递推)'!Q16+'Y(递推)'!O15+'Y(递推)'!P15+1,2) -> 0 | AS17: =MOD(AS7-AL7,2) -> 0 | AT17: =MOD(AT7-AM7,2) -> 1 | AU17: =MOD(AU7-AN7,2) -> 1 | AV17: =MOD(AV7-AO7,2) -> 1 | AW17: =MOD(AW7-AP7,2) -> 0 | AX17: =MOD(AX7-AQ7,2) -> 0
C18: =MOD(A17+B17+C17+A16+'Y(递推)'!A17+'Y(递推)'!B17+'Y(递推)'!C17+'Y(递推)'!A16+'Y(递推)'!B16+1,2) -> 1 | D18: =MOD(B17+C17+D17+B16+'Y(递推)'!B17+'Y(递推)'!C17+'Y(递推)'!D17+'Y(递推)'!B16+'Y(递推)'!C16+1,2) -> 1 | E18: =MOD(C17+D17+E17+C16+'Y(递推)'!C17+'Y(递推)'!D17+'Y(递推)'!E17+'Y(递推)'!C16+'Y(递推)'!D16+1,2) -> 0 | F18: =MOD(D17+E17+F17+D16+'Y(递推)'!D17+'Y(递推)'!E17+'Y(递推)'!F17+'Y(递推)'!D16+'Y(递推)'!E16+1,2) -> 1 | G18: =MOD(E17+F17+G17+E16+'Y(递推)'!E17+'Y(递推)'!F17+'Y(递推)'!G17+'Y(递推)'!E16+'Y(递推)'!F16+1,2) -> 0 | H18: =MOD(F17+G17+H17+F16+'Y(递推)'!F17+'Y(递推)'!G17+'Y(递推)'!H17+'Y(递推)'!F16+'Y(递推)'!G16+1,2) -> 0 | I18: =MOD(G17+H17+I17+G16+'Y(递推)'!G17+'Y(递推)'!H17+'Y(递推)'!I17+'Y(递推)'!G16+'Y(递推)'!H16+1,2) -> 0 | J18: =MOD(H17+I17+J17+H16+'Y(递推)'!H17+'Y(递推)'!I17+'Y(递推)'!J17+'Y(递推)'!H16+'Y(递推)'!I16+1,2) -> 1 | ... R18: =MOD(P17+Q17+R17+P16+'Y(递推)'!P17+'Y(递推)'!Q17+'Y(递推)'!R17+'Y(递推)'!P16+'Y(递推)'!Q16+1,2) -> 1 | AS18: =MOD(AS8-AL8,2) -> 1 | AT18: =MOD(AT8-AM8,2) -> 0 | AU18: =MOD(AU8-AN8,2) -> 0 | AV18: =MOD(AV8-AO8,2) -> 0 | AW18: =MOD(AW8-AP8,2) -> 1 | AX18: =MOD(AX8-AQ8,2) -> 0
C19: =MOD(A18+B18+C18+A17+'Y(递推)'!A18+'Y(递推)'!B18+'Y(递推)'!C18+'Y(递推)'!A17+'Y(递推)'!B17+1,2) -> 0 | D19: =MOD(B18+C18+D18+B17+'Y(递推)'!B18+'Y(递推)'!C18+'Y(递推)'!D18+'Y(递推)'!B17+'Y(递推)'!C17+1,2) -> 1 | E19: =MOD(C18+D18+E18+C17+'Y(递推)'!C18+'Y(递推)'!D18+'Y(递推)'!E18+'Y(递推)'!C17+'Y(递推)'!D17+1,2) -> 0 | F19: =MOD(D18+E18+F18+D17+'Y(递推)'!D18+'Y(递推)'!E18+'Y(递推)'!F18+'Y(递推)'!D17+'Y(递推)'!E17+1,2) -> 0 | G19: =MOD(E18+F18+G18+E17+'Y(递推)'!E18+'Y(递推)'!F18+'Y(递推)'!G18+'Y(递推)'!E17+'Y(递推)'!F17+1,2) -> 1 | H19: =MOD(F18+G18+H18+F17+'Y(递推)'!F18+'Y(递推)'!G18+'Y(递推)'!H18+'Y(递推)'!F17+'Y(递推)'!G17+1,2) -> 0 | I19: =MOD(G18+H18+I18+G17+'Y(递推)'!G18+'Y(递推)'!H18+'Y(递推)'!I18+'Y(递推)'!G17+'Y(递推)'!H17+1,2) -> 1 | J19: =MOD(H18+I18+J18+H17+'Y(递推)'!H18+'Y(递推)'!I18+'Y(递推)'!J18+'Y(递推)'!H17+'Y(递推)'!I17+1,2) -> 0 | ... S19: =MOD(Q18+R18+S18+Q17+'Y(递推)'!Q18+'Y(递推)'!R18+'Y(递推)'!S18+'Y(递推)'!Q17+'Y(递推)'!R17+1,2) -> 0 | AS19: =MOD(AS9-AL9,2) -> 1 | AT19: =MOD(AT9-AM9,2) -> 0 | AU19: =MOD(AU9-AN9,2) -> 0 | AV19: =MOD(AV9-AO9,2) -> 0 | AW19: =MOD(AW9-AP9,2) -> 0 | AX19: =MOD(AX9-AQ9,2) -> 1
C20: =MOD(A19+B19+C19+A18+'Y(递推)'!A19+'Y(递推)'!B19+'Y(递推)'!C19+'Y(递推)'!A18+'Y(递推)'!B18+1,2) -> 0 | D20: =MOD(B19+C19+D19+B18+'Y(递推)'!B19+'Y(递推)'!C19+'Y(递推)'!D19+'Y(递推)'!B18+'Y(递推)'!C18+1,2) -> 1 | E20: =MOD(C19+D19+E19+C18+'Y(递推)'!C19+'Y(递推)'!D19+'Y(递推)'!E19+'Y(递推)'!C18+'Y(递推)'!D18+1,2) -> 1 | F20: =MOD(D19+E19+F19+D18+'Y(递推)'!D19+'Y(递推)'!E19+'Y(递推)'!F19+'Y(递推)'!D18+'Y(递推)'!E18+1,2) -> 1 | G20: =MOD(E19+F19+G19+E18+'Y(递推)'!E19+'Y(递推)'!F19+'Y(递推)'!G19+'Y(递推)'!E18+'Y(递推)'!F18+1,2) -> 1 | H20: =MOD(F19+G19+H19+F18+'Y(递推)'!F19+'Y(递推)'!G19+'Y(递推)'!H19+'Y(递推)'!F18+'Y(递推)'!G18+1,2) -> 1 | I20: =MOD(G19+H19+I19+G18+'Y(递推)'!G19+'Y(递推)'!H19+'Y(递推)'!I19+'Y(递推)'!G18+'Y(递推)'!H18+1,2) -> 0 | J20: =MOD(H19+I19+J19+H18+'Y(递推)'!H19+'Y(递推)'!I19+'Y(递推)'!J19+'Y(递推)'!H18+'Y(递推)'!I18+1,2) -> 1 | ... T20: =MOD(R19+S19+T19+R18+'Y(递推)'!R19+'Y(递推)'!S19+'Y(递推)'!T19+'Y(递推)'!R18+'Y(递推)'!S18+1,2) -> 0
C21: =MOD(A20+B20+C20+A19+'Y(递推)'!A20+'Y(递推)'!B20+'Y(递推)'!C20+'Y(递推)'!A19+'Y(递推)'!B19+1,2) -> 1 | D21: =MOD(B20+C20+D20+B19+'Y(递推)'!B20+'Y(递推)'!C20+'Y(递推)'!D20+'Y(递推)'!B19+'Y(递推)'!C19+1,2) -> 1 | E21: =MOD(C20+D20+E20+C19+'Y(递推)'!C20+'Y(递推)'!D20+'Y(递推)'!E20+'Y(递推)'!C19+'Y(递推)'!D19+1,2) -> 1 | F21: =MOD(D20+E20+F20+D19+'Y(递推)'!D20+'Y(递推)'!E20+'Y(递推)'!F20+'Y(递推)'!D19+'Y(递推)'!E19+1,2) -> 0 | G21: =MOD(E20+F20+G20+E19+'Y(递推)'!E20+'Y(递推)'!F20+'Y(递推)'!G20+'Y(递推)'!E19+'Y(递推)'!F19+1,2) -> 1 | H21: =MOD(F20+G20+H20+F19+'Y(递推)'!F20+'Y(递推)'!G20+'Y(递推)'!H20+'Y(递推)'!F19+'Y(递推)'!G19+1,2) -> 1 | I21: =MOD(G20+H20+I20+G19+'Y(递推)'!G20+'Y(递推)'!H20+'Y(递推)'!I20+'Y(递推)'!G19+'Y(递推)'!H19+1,2) -> 1 | J21: =MOD(H20+I20+J20+H19+'Y(递推)'!H20+'Y(递推)'!I20+'Y(递推)'!J20+'Y(递推)'!H19+'Y(递推)'!I19+1,2) -> 0 | ... U21: =MOD(S20+T20+U20+S19+'Y(递推)'!S20+'Y(递推)'!T20+'Y(递推)'!U20+'Y(递推)'!S19+'Y(递推)'!T19+1,2) -> 1
C22: =MOD(A21+B21+C21+A20+'Y(递推)'!A21+'Y(递推)'!B21+'Y(递推)'!C21+'Y(递推)'!A20+'Y(递推)'!B20+1,2) -> 0 | D22: =MOD(B21+C21+D21+B20+'Y(递推)'!B21+'Y(递推)'!C21+'Y(递推)'!D21+'Y(递推)'!B20+'Y(递推)'!C20+1,2) -> 1 | E22: =MOD(C21+D21+E21+C20+'Y(递推)'!C21+'Y(递推)'!D21+'Y(递推)'!E21+'Y(递推)'!C20+'Y(递推)'!D20+1,2) -> 0 | F22: =MOD(D21+E21+F21+D20+'Y(递推)'!D21+'Y(递推)'!E21+'Y(递推)'!F21+'Y(递推)'!D20+'Y(递推)'!E20+1,2) -> 0 | G22: =MOD(E21+F21+G21+E20+'Y(递推)'!E21+'Y(递推)'!F21+'Y(递推)'!G21+'Y(递推)'!E20+'Y(递推)'!F20+1,2) -> 0 | H22: =MOD(F21+G21+H21+F20+'Y(递推)'!F21+'Y(递推)'!G21+'Y(递推)'!H21+'Y(递推)'!F20+'Y(递推)'!G20+1,2) -> 1 | I22: =MOD(G21+H21+I21+G20+'Y(递推)'!G21+'Y(递推)'!H21+'Y(递推)'!I21+'Y(递推)'!G20+'Y(递推)'!H20+1,2) -> 1 | J22: =MOD(H21+I21+J21+H20+'Y(递推)'!H21+'Y(递推)'!I21+'Y(递推)'!J21+'Y(递推)'!H20+'Y(递推)'!I20+1,2) -> 0 | ... V22: =MOD(T21+U21+V21+T20+'Y(递推)'!T21+'Y(递推)'!U21+'Y(递推)'!V21+'Y(递推)'!T20+'Y(递推)'!U20+1,2) -> 0

Sheet Y(递推)
A1: n-1
B3: ='Y(灯)'!C3 -> 1 | C3: =MOD(B2+C2+D2+C1,2) -> 0 | D3: =MOD(C2+D2+E2+D1,2) -> 0 | E3: =MOD(D2+E2+F2+E1,2) -> 0 | F3: =MOD(E2+F2+G2+F1,2) -> 0 | G3: =MOD(F2+G2+H2+G1,2) -> 0 | H3: =MOD(G2+H2+I2+H1,2) -> 0 | I3: =MOD(H2+I2+J2+I1,2) -> 0 | J3: =MOD(I2+J2+K2+J1,2) -> 0 | ... U3: =MOD(T2+U2+V2+U1,2) -> 0
B4: ='Y(灯)'!C4 -> 1 | C4: =MOD(B3+C3+D3+C2,2) -> 1 | D4: =MOD(C3+D3+E3+D2,2) -> 0 | E4: =MOD(D3+E3+F3+E2,2) -> 0 | F4: =MOD(E3+F3+G3+F2,2) -> 0 | G4: =MOD(F3+G3+H3+G2,2) -> 0 | H4: =MOD(G3+H3+I3+H2,2) -> 0 | I4: =MOD(H3+I3+J3+I2,2) -> 0 | J4: =MOD(I3+J3+K3+J2,2) -> 0 | ... U4: =MOD(T3+U3+V3+U2,2) -> 0
B5: ='Y(灯)'!C5 -> 1 | C5: =MOD(B4+C4+D4+C3,2) -> 0 | D5: =MOD(C4+D4+E4+D3,2) -> 1 | E5: =MOD(D4+E4+F4+E3,2) -> 0 | F5: =MOD(E4+F4+G4+F3,2) -> 0 | G5: =MOD(F4+G4+H4+G3,2) -> 0 | H5: =MOD(G4+H4+I4+H3,2) -> 0 | I5: =MOD(H4+I4+J4+I3,2) -> 0 | J5: =MOD(I4+J4+K4+J3,2) -> 0 | ... U5: =MOD(T4+U4+V4+U3,2) -> 0
B6: ='Y(灯)'!C6 -> 0 | C6: =MOD(B5+C5+D5+C4,2) -> 1 | D6: =MOD(C5+D5+E5+D4,2) -> 1 | E6: =MOD(D5+E5+F5+E4,2) -> 1 | F6: =MOD(E5+F5+G5+F4,2) -> 0 | G6: =MOD(F5+G5+H5+G4,2) -> 0 | H6: =MOD(G5+H5+I5+H4,2) -> 0 | I6: =MOD(H5+I5+J5+I4,2) -> 0 | J6: =MOD(I5+J5+K5+J4,2) -> 0 | ... U6: =MOD(T5+U5+V5+U4,2) -> 0
B7: ='Y(灯)'!C7 -> 1 | C7: =MOD(B6+C6+D6+C5,2) -> 0 | D7: =MOD(C6+D6+E6+D5,2) -> 0 | E7: =MOD(D6+E6+F6+E5,2) -> 0 | F7: =MOD(E6+F6+G6+F5,2) -> 1 | G7: =MOD(F6+G6+H6+G5,2) -> 0 | H7: =MOD(G6+H6+I6+H5,2) -> 0 | I7: =MOD(H6+I6+J6+I5,2) -> 0 | J7: =MOD(I6+J6+K6+J5,2) -> 0 | ... U7: =MOD(T6+U6+V6+U5,2) -> 0
B8: ='Y(灯)'!C8 -> 1 | C8: =MOD(B7+C7+D7+C6,2) -> 0 | D8: =MOD(C7+D7+E7+D6,2) -> 1 | E8: =MOD(D7+E7+F7+E6,2) -> 0 | F8: =MOD(E7+F7+G7+F6,2) -> 1 | G8: =MOD(F7+G7+H7+G6,2) -> 1 | H8: =MOD(G7+H7+I7+H6,2) -> 0 | I8: =MOD(H7+I7+J7+I6,2) -> 0 | J8: =MOD(I7+J7+K7+J6,2) -> 0 | ... U8: =MOD(T7+U7+V7+U6,2) -> 0
B9: ='Y(灯)'!C9 -> 0 | C9: =MOD(B8+C8+D8+C7,2) -> 0 | D9: =MOD(C8+D8+E8+D7,2) -> 1 | E9: =MOD(D8+E8+F8+E7,2) -> 0 | F9: =MOD(E8+F8+G8+F7,2) -> 1 | G9: =MOD(F8+G8+H8+G7,2) -> 0 | H9: =MOD(G8+H8+I8+H7,2) -> 1 | I9: =MOD(H8+I8+J8+I7,2) -> 0 | J9: =MOD(I8+J8+K8+J7,2) -> 0 | ... U9: =MOD(T8+U8+V8+U7,2) -> 0
B10: ='Y(灯)'!C10 -> 0 | C10: =MOD(B9+C9+D9+C8,2) -> 1 | D10: =MOD(C9+D9+E9+D8,2) -> 0 | E10: =MOD(D9+E9+F9+E8,2) -> 0 | F10: =MOD(E9+F9+G9+F8,2) -> 0 | G10: =MOD(F9+G9+H9+G8,2) -> 1 | H10: =MOD(G9+H9+I9+H8,2) -> 1 | I10: =MOD(H9+I9+J9+I8,2) -> 1 | J10: =MOD(I9+J9+K9+J8,2) -> 0 | ... U10: =MOD(T9+U9+V9+U8,2) -> 0
B11: ='Y(灯)'!C11 -> 0 | C11: =MOD(B10+C10+D10+C9,2) -> 1 | D11: =MOD(C10+D10+E10+D9,2) -> 0 | E11: =MOD(D10+E10+F10+E9,2) -> 0 | F11: =MOD(E10+F10+G10+F9,2) -> 0 | G11: =MOD(F10+G10+H10+G9,2) -> 0 | H11: =MOD(G10+H10+I10+H9,2) -> 0 | I11: =MOD(H10+I10+J10+I9,2) -> 0 | J11: =MOD(I10+J10+K10+J9,2) -> 1 | ... U11: =MOD(T10+U10+V10+U9,2) -> 0
B12: ='Y(灯)'!C12 -> 0 | C12: =MOD(B11+C11+D11+C10,2) -> 0 | D12: =MOD(C11+D11+E11+D10,2) -> 1 | E12: =MOD(D11+E11+F11+E10,2) -> 0 | F12: =MOD(E11+F11+G11+F10,2) -> 0 | G12: =MOD(F11+G11+H11+G10,2) -> 1 | H12: =MOD(G11+H11+I11+H10,2) -> 1 | I12: =MOD(H11+I11+J11+I10,2) -> 0 | J12: =MOD(I11+J11+K11+J10,2) -> 1 | ... U12: =MOD(T11+U11+V11+U10,2) -> 0
B13: ='Y(灯)'!C13 -> 1 | C13: =MOD(B12+C12+D12+C11,2) -> 0 | D13: =MOD(C12+D12+E12+D11,2) -> 1 | E13: =MOD(D12+E12+F12+E11,2) -> 1 | F13: =MOD(E12+F12+G12+F11,2) -> 1 | G13: =MOD(F12+G12+H12+G11,2) -> 0 | H13: =MOD(G12+H12+I12+H11,2) -> 0 | I13: =MOD(H12+I12+J12+I11,2) -> 0 | J13: =MOD(I12+J12+K12+J11,2) -> 1 | ... U13: =MOD(T12+U12+V12+U11,2) -> 0
B14: ='Y(灯)'!C14 -> 1 | C14: =MOD(B13+C13+D13+C12,2) -> 0 | D14: =MOD(C13+D13+E13+D12,2) -> 1 | E14: =MOD(D13+E13+F13+E12,2) -> 1 | F14: =MOD(E13+F13+G13+F12,2) -> 0 | G14: =MOD(F13+G13+H13+G12,2) -> 0 | H14: =MOD(G13+H13+I13+H12,2) -> 1 | I14: =MOD(H13+I13+J13+I12,2) -> 1 | J14: =MOD(I13+J13+K13+J12,2) -> 0 | ... U14: =MOD(T13+U13+V13+U12,2) -> 0
... B22: ='Y(灯)'!C22 -> 0 | C22: =MOD(B21+C21+D21+C20,2) -> 0 | D22: =MOD(C21+D21+E21+D20,2) -> 0 | E22: =MOD(D21+E21+F21+E20,2) -> 1 | F22: =MOD(E21+F21+G21+F20,2) -> 0 | G22: =MOD(F21+G21+H21+G20,2) -> 0 | H22: =MOD(G21+H21+I21+H20,2) -> 1 | I22: =MOD(H21+I21+J21+I20,2) -> 1 | J22: =MOD(I21+J21+K21+J20,2) -> 1 | ... U22: =MOD(T21+U21+V21+U20,2) -> 1

Sheet Y1
A1: n-1
B3: =MOD('Y(灯)'!B2+'Y(递推)'!B2,2) -> 0 | C3: =MOD('Y(灯)'!C2+'Y(递推)'!C2,2) -> 0 | D3: =MOD('Y(灯)'!D2+'Y(递推)'!D2,2) -> 0 | E3: =MOD('Y(灯)'!E2+'Y(递推)'!E2,2) -> 0 | F3: =MOD('Y(灯)'!F2+'Y(递推)'!F2,2) -> 0 | G3: =MOD('Y(灯)'!G2+'Y(递推)'!G2,2) -> 0 | H3: =MOD('Y(灯)'!H2+'Y(递推)'!H2,2) -> 0 | I3: =MOD('Y(灯)'!I2+'Y(递推)'!I2,2) -> 0 | ... U3: =MOD('Y(灯)'!U2+'Y(递推)'!U2,2) -> 0
B4: =MOD('Y(灯)'!B3+'Y(递推)'!B3,2) -> 1 | C4: =MOD('Y(灯)'!C3+'Y(递推)'!C3,2) -> 1 | D4: =MOD('Y(灯)'!D3+'Y(递推)'!D3,2) -> 0 | E4: =MOD('Y(灯)'!E3+'Y(递推)'!E3,2) -> 0 | F4: =MOD('Y(灯)'!F3+'Y(递推)'!F3,2) -> 0 | G4: =MOD('Y(灯)'!G3+'Y(递推)'!G3,2) -> 0 | H4: =MOD('Y(灯)'!H3+'Y(递推)'!H3,2) -> 0 | I4: =MOD('Y(灯)'!I3+'Y(递推)'!I3,2) -> 0 | ... U4: =MOD('Y(灯)'!U3+'Y(递推)'!U3,2) -> 0
B5: =MOD('Y(灯)'!B4+'Y(递推)'!B4,2) -> 1 | C5: =MOD('Y(灯)'!C4+'Y(递推)'!C4,2) -> 0 | D5: =MOD('Y(灯)'!D4+'Y(递推)'!D4,2) -> 1 | E5: =MOD('Y(灯)'!E4+'Y(递推)'!E4,2) -> 0 | F5: =MOD('Y(灯)'!F4+'Y(递推)'!F4,2) -> 0 | G5: =MOD('Y(灯)'!G4+'Y(递推)'!G4,2) -> 0 | H5: =MOD('Y(灯)'!H4+'Y(递推)'!H4,2) -> 0 | I5: =MOD('Y(灯)'!I4+'Y(递推)'!I4,2) -> 0 | ... U5: =MOD('Y(灯)'!U4+'Y(递推)'!U4,2) -> 0
B6: =MOD('Y(灯)'!B5+'Y(递推)'!B5,2) -> 1 | C6: =MOD('Y(灯)'!C5+'Y(递推)'!C5,2) -> 1 | D6: =MOD('Y(灯)'!D5+'Y(递推)'!D5,2) -> 1 | E6: =MOD('Y(灯)'!E5+'Y(递推)'!E5,2) -> 1 | F6: =MOD('Y(灯)'!F5+'Y(递推)'!F5,2) -> 0 | G6: =MOD('Y(灯)'!G5+'Y(递推)'!G5,2) -> 0 | H6: =MOD('Y(灯)'!H5+'Y(递推)'!H5,2) -> 0 | I6: =MOD('Y(灯)'!I5+'Y(递推)'!I5,2) -> 0 | ... U6: =MOD('Y(灯)'!U5+'Y(递推)'!U5,2) -> 0
B7: =MOD('Y(灯)'!B6+'Y(递推)'!B6,2) -> 0 | C7: =MOD('Y(灯)'!C6+'Y(递推)'!C6,2) -> 1 | D7: =MOD('Y(灯)'!D6+'Y(递推)'!D6,2) -> 1 | E7: =MOD('Y(灯)'!E6+'Y(递推)'!E6,2) -> 1 | F7: =MOD('Y(灯)'!F6+'Y(递推)'!F6,2) -> 0 | G7: =MOD('Y(灯)'!G6+'Y(递推)'!G6,2) -> 0 | H7: =MOD('Y(灯)'!H6+'Y(递推)'!H6,2) -> 0 | I7: =MOD('Y(灯)'!I6+'Y(递推)'!I6,2) -> 0 | ... U7: =MOD('Y(灯)'!U6+'Y(递推)'!U6,2) -> 0
B8: =MOD('Y(灯)'!B7+'Y(递推)'!B7,2) -> 1 | C8: =MOD('Y(灯)'!C7+'Y(递推)'!C7,2) -> 1 | D8: =MOD('Y(灯)'!D7+'Y(递推)'!D7,2) -> 0 | E8: =MOD('Y(灯)'!E7+'Y(递推)'!E7,2) -> 0 | F8: =MOD('Y(灯)'!F7+'Y(递推)'!F7,2) -> 1 | G8: =MOD('Y(灯)'!G7+'Y(递推)'!G7,2) -> 1 | H8: =MOD('Y(灯)'!H7+'Y(递推)'!H7,2) -> 0 | I8: =MOD('Y(灯)'!I7+'Y(递推)'!I7,2) -> 0 | ... U8: =MOD('Y(灯)'!U7+'Y(递推)'!U7,2) -> 0
B9: =MOD('Y(灯)'!B8+'Y(递推)'!B8,2) -> 1 | C9: =MOD('Y(灯)'!C8+'Y(递推)'!C8,2) -> 1 | D9: =MOD('Y(灯)'!D8+'Y(递推)'!D8,2) -> 1 | E9: =MOD('Y(灯)'!E8+'Y(递推)'!E8,2) -> 0 | F9: =MOD('Y(灯)'!F8+'Y(递推)'!F8,2) -> 1 | G9: =MOD('Y(灯)'!G8+'Y(递推)'!G8,2) -> 1 | H9: =MOD('Y(灯)'!H8+'Y(递推)'!H8,2) -> 1 | I9: =MOD('Y(灯)'!I8+'Y(递推)'!I8,2) -> 0 | ... U9: =MOD('Y(灯)'!U8+'Y(递推)'!U8,2) -> 0
B10: =MOD('Y(灯)'!B9+'Y(递推)'!B9,2) -> 0 | C10: =MOD('Y(灯)'!C9+'Y(递推)'!C9,2) -> 0 | D10: =MOD('Y(灯)'!D9+'Y(递推)'!D9,2) -> 0 | E10: =MOD('Y(灯)'!E9+'Y(递推)'!E9,2) -> 0 | F10: =MOD('Y(灯)'!F9+'Y(递推)'!F9,2) -> 0 | G10: =MOD('Y(灯)'!G9+'Y(递推)'!G9,2) -> 0 | H10: =MOD('Y(灯)'!H9+'Y(递推)'!H9,2) -> 0 | I10: =MOD('Y(灯)'!I9+'Y(递推)'!I9,2) -> 0 | ... U10: =MOD('Y(灯)'!U9+'Y(递推)'!U9,2) -> 0
B11: =MOD('Y(灯)'!B10+'Y(递推)'!B10,2) -> 0 | C11: =MOD('Y(灯)'!C10+'Y(递推)'!C10,2) -> 1 | D11: =MOD('Y(灯)'!D10+'Y(递推)'!D10,2) -> 0 | E11: =MOD('Y(灯)'!E10+'Y(递推)'!E10,2) -> 1 | F11: =MOD('Y(灯)'!F10+'Y(递推)'!F10,2) -> 0 | G11: =MOD('Y(灯)'!G10+'Y(递推)'!G10,2) -> 1 | H11: =MOD('Y(灯)'!H10+'Y(递推)'!H10,2) -> 0 | I11: =MOD('Y(灯)'!I10+'Y(递推)'!I10,2) -> 1 | ... U11: =MOD('Y(灯)'!U10+'Y(递推)'!U10,2) -> 0
B12: =MOD('Y(灯)'!B11+'Y(递推)'!B11,2) -> 0 | C12: =MOD('Y(灯)'!C11+'Y(递推)'!C11,2) -> 1 | D12: =MOD('Y(灯)'!D11+'Y(递推)'!D11,2) -> 0 | E12: =MOD('Y(灯)'!E11+'Y(递推)'!E11,2) -> 0 | F12: =MOD('Y(灯)'!F11+'Y(递推)'!F11,2) -> 0 | G12: =MOD('Y(灯)'!G11+'Y(递推)'!G11,2) -> 0 | H12: =MOD('Y(灯)'!H11+'Y(递推)'!H11,2) -> 0 | I12: =MOD('Y(灯)'!I11+'Y(递推)'!I11,2) -> 0 | ... U12: =MOD('Y(灯)'!U11+'Y(递推)'!U11,2) -> 0
B13: =MOD('Y(灯)'!B12+'Y(递推)'!B12,2) -> 0 | C13: =MOD('Y(灯)'!C12+'Y(递推)'!C12,2) -> 0 | D13: =MOD('Y(灯)'!D12+'Y(递推)'!D12,2) -> 0 | E13: =MOD('Y(灯)'!E12+'Y(递推)'!E12,2) -> 1 | F13: =MOD('Y(灯)'!F12+'Y(递推)'!F12,2) -> 1 | G13: =MOD('Y(灯)'!G12+'Y(递推)'!G12,2) -> 1 | H13: =MOD('Y(灯)'!H12+'Y(递推)'!H12,2) -> 1 | I13: =MOD('Y(灯)'!I12+'Y(递推)'!I12,2) -> 1 | ... U13: =MOD('Y(灯)'!U12+'Y(递推)'!U12,2) -> 0
B14: =MOD('Y(灯)'!B13+'Y(递推)'!B13,2) -> 1 | C14: =MOD('Y(灯)'!C13+'Y(递推)'!C13,2) -> 1 | D14: =MOD('Y(灯)'!D13+'Y(递推)'!D13,2) -> 1 | E14: =MOD('Y(灯)'!E13+'Y(递推)'!E13,2) -> 0 | F14: =MOD('Y(灯)'!F13+'Y(递推)'!F13,2) -> 0 | G14: =MOD('Y(灯)'!G13+'Y(递推)'!G13,2) -> 0 | H14: =MOD('Y(灯)'!H13+'Y(递推)'!H13,2) -> 0 | I14: =MOD('Y(灯)'!I13+'Y(递推)'!I13,2) -> 0 | ... U14: =MOD('Y(灯)'!U13+'Y(递推)'!U13,2) -> 0
... B22: =MOD('Y(灯)'!B21+'Y(递推)'!B21,2) -> 1 | C22: =MOD('Y(灯)'!C21+'Y(递推)'!C21,2) -> 0 | D22: =MOD('Y(灯)'!D21+'Y(递推)'!D21,2) -> 1 | E22: =MOD('Y(灯)'!E21+'Y(递推)'!E21,2) -> 1 | F22: =MOD('Y(灯)'!F21+'Y(递推)'!F21,2) -> 1 | G22: =MOD('Y(灯)'!G21+'Y(递推)'!G21,2) -> 1 | H22: =MOD('Y(灯)'!H21+'Y(递推)'!H21,2) -> 1 | I22: =MOD('Y(灯)'!I21+'Y(递推)'!I21,2) -> 1 | ... U22: =MOD('Y(灯)'!U21+'Y(递推)'!U21,2) -> 1

Sheet Y2
A1: n-1
B3: =MOD('Y1'!A2+'Y(递推)'!B1,2) -> 0 | C3: =MOD('Y1'!B2+'Y(递推)'!C1,2) -> 0 | D3: =MOD('Y1'!C2+'Y(递推)'!D1,2) -> 0 | E3: =MOD('Y1'!D2+'Y(递推)'!E1,2) -> 0 | F3: =MOD('Y1'!E2+'Y(递推)'!F1,2) -> 0 | G3: =MOD('Y1'!F2+'Y(递推)'!G1,2) -> 0 | H3: =MOD('Y1'!G2+'Y(递推)'!H1,2) -> 0 | I3: =MOD('Y1'!H2+'Y(递推)'!I1,2) -> 0 | ... U3: =MOD('Y1'!T2+'Y(递推)'!U1,2) -> 0
B4: =MOD('Y1'!A3+'Y(递推)'!B2,2) -> 0 | C4: =MOD('Y1'!B3+'Y(递推)'!C2,2) -> 0 | D4: =MOD('Y1'!C3+'Y(递推)'!D2,2) -> 0 | E4: =MOD('Y1'!D3+'Y(递推)'!E2,2) -> 0 | F4: =MOD('Y1'!E3+'Y(递推)'!F2,2) -> 0 | G4: =MOD('Y1'!F3+'Y(递推)'!G2,2) -> 0 | H4: =MOD('Y1'!G3+'Y(递推)'!H2,2) -> 0 | I4: =MOD('Y1'!H3+'Y(递推)'!I2,2) -> 0 | ... U4: =MOD('Y1'!T3+'Y(递推)'!U2,2) -> 0
B5: =MOD('Y1'!A4+'Y(递推)'!B3,2) -> 1 | C5: =MOD('Y1'!B4+'Y(递推)'!C3,2) -> 1 | D5: =MOD('Y1'!C4+'Y(递推)'!D3,2) -> 1 | E5: =MOD('Y1'!D4+'Y(递推)'!E3,2) -> 0 | F5: =MOD('Y1'!E4+'Y(递推)'!F3,2) -> 0 | G5: =MOD('Y1'!F4+'Y(递推)'!G3,2) -> 0 | H5: =MOD('Y1'!G4+'Y(递推)'!H3,2) -> 0 | I5: =MOD('Y1'!H4+'Y(递推)'!I3,2) -> 0 | ... U5: =MOD('Y1'!T4+'Y(递推)'!U3,2) -> 0
B6: =MOD('Y1'!A5+'Y(递推)'!B4,2) -> 1 | C6: =MOD('Y1'!B5+'Y(递推)'!C4,2) -> 0 | D6: =MOD('Y1'!C5+'Y(递推)'!D4,2) -> 0 | E6: =MOD('Y1'!D5+'Y(递推)'!E4,2) -> 1 | F6: =MOD('Y1'!E5+'Y(递推)'!F4,2) -> 0 | G6: =MOD('Y1'!F5+'Y(递推)'!G4,2) -> 0 | H6: =MOD('Y1'!G5+'Y(递推)'!H4,2) -> 0 | I6: =MOD('Y1'!H5+'Y(递推)'!I4,2) -> 0 | ... U6: =MOD('Y1'!T5+'Y(递推)'!U4,2) -> 0
B7: =MOD('Y1'!A6+'Y(递推)'!B5,2) -> 1 | C7: =MOD('Y1'!B6+'Y(递推)'!C5,2) -> 1 | D7: =MOD('Y1'!C6+'Y(递推)'!D5,2) -> 0 | E7: =MOD('Y1'!D6+'Y(递推)'!E5,2) -> 1 | F7: =MOD('Y1'!E6+'Y(递推)'!F5,2) -> 1 | G7: =MOD('Y1'!F6+'Y(递推)'!G5,2) -> 0 | H7: =MOD('Y1'!G6+'Y(递推)'!H5,2) -> 0 | I7: =MOD('Y1'!H6+'Y(递推)'!I5,2) -> 0 | ... U7: =MOD('Y1'!T6+'Y(递推)'!U5,2) -> 0
B8: =MOD('Y1'!A7+'Y(递推)'!B6,2) -> 0 | C8: =MOD('Y1'!B7+'Y(递推)'!C6,2) -> 1 | D8: =MOD('Y1'!C7+'Y(递推)'!D6,2) -> 0 | E8: =MOD('Y1'!D7+'Y(递推)'!E6,2) -> 0 | F8: =MOD('Y1'!E7+'Y(递推)'!F6,2) -> 1 | G8: =MOD('Y1'!F7+'Y(递推)'!G6,2) -> 0 | H8: =MOD('Y1'!G7+'Y(递推)'!H6,2) -> 0 | I8: =MOD('Y1'!H7+'Y(递推)'!I6,2) -> 0 | ... U8: =MOD('Y1'!T7+'Y(递推)'!U6,2) -> 0
B9: =MOD('Y1'!A8+'Y(递推)'!B7,2) -> 1 | C9: =MOD('Y1'!B8+'Y(递推)'!C7,2) -> 1 | D9: =MOD('Y1'!C8+'Y(递推)'!D7,2) -> 1 | E9: =MOD('Y1'!D8+'Y(递推)'!E7,2) -> 0 | F9: =MOD('Y1'!E8+'Y(递推)'!F7,2) -> 1 | G9: =MOD('Y1'!F8+'Y(递推)'!G7,2) -> 1 | H9: =MOD('Y1'!G8+'Y(递推)'!H7,2) -> 1 | I9: =MOD('Y1'!H8+'Y(递推)'!I7,2) -> 0 | ... U9: =MOD('Y1'!T8+'Y(递推)'!U7,2) -> 0
B10: =MOD('Y1'!A9+'Y(递推)'!B8,2) -> 1 | C10: =MOD('Y1'!B9+'Y(递推)'!C8,2) -> 1 | D10: =MOD('Y1'!C9+'Y(递推)'!D8,2) -> 0 | E10: =MOD('Y1'!D9+'Y(递推)'!E8,2) -> 1 | F10: =MOD('Y1'!E9+'Y(递推)'!F8,2) -> 1 | G10: =MOD('Y1'!F9+'Y(递推)'!G8,2) -> 0 | H10: =MOD('Y1'!G9+'Y(递推)'!H8,2) -> 1 | I10: =MOD('Y1'!H9+'Y(递推)'!I8,2) -> 1 | ... U10: =MOD('Y1'!T9+'Y(递推)'!U8,2) -> 0
B11: =MOD('Y1'!A10+'Y(递推)'!B9,2) -> 0 | C11: =MOD('Y1'!B10+'Y(递推)'!C9,2) -> 0 | D11: =MOD('Y1'!C10+'Y(递推)'!D9,2) -> 1 | E11: =MOD('Y1'!D10+'Y(递推)'!E9,2) -> 0 | F11: =MOD('Y1'!E10+'Y(递推)'!F9,2) -> 1 | G11: =MOD('Y1'!F10+'Y(递推)'!G9,2) -> 0 | H11: =MOD('Y1'!G10+'Y(递推)'!H9,2) -> 1 | I11: =MOD('Y1'!H10+'Y(递推)'!I9,2) -> 0 | ... U11: =MOD('Y1'!T10+'Y(递推)'!U9,2) -> 0
B12: =MOD('Y1'!A11+'Y(递推)'!B10,2) -> 0 | C12: =MOD('Y1'!B11+'Y(递推)'!C10,2) -> 1 | D12: =MOD('Y1'!C11+'Y(递推)'!D10,2) -> 1 | E12: =MOD('Y1'!D11+'Y(递推)'!E10,2) -> 0 | F12: =MOD('Y1'!E11+'Y(递推)'!F10,2) -> 1 | G12: =MOD('Y1'!F11+'Y(递推)'!G10,2) -> 1 | H12: =MOD('Y1'!G11+'Y(递推)'!H10,2) -> 0 | I12: =MOD('Y1'!H11+'Y(递推)'!I10,2) -> 1 | ... U12: =MOD('Y1'!T11+'Y(递推)'!U10,2) -> 0
B13: =MOD('Y1'!A12+'Y(递推)'!B11,2) -> 0 | C13: =MOD('Y1'!B12+'Y(递推)'!C11,2) -> 1 | D13: =MOD('Y1'!C12+'Y(递推)'!D11,2) -> 1 | E13: =MOD('Y1'!D12+'Y(递推)'!E11,2) -> 0 | F13: =MOD('Y1'!E12+'Y(递推)'!F11,2) -> 0 | G13: =MOD('Y1'!F12+'Y(递推)'!G11,2) -> 0 | H13: =MOD('Y1'!G12+'Y(递推)'!H11,2) -> 0 | I13: =MOD('Y1'!H12+'Y(递推)'!I11,2) -> 0 | ... U13: =MOD('Y1'!T12+'Y(递推)'!U11,2) -> 0
B14: =MOD('Y1'!A13+'Y(递推)'!B12,2) -> 0 | C14: =MOD('Y1'!B13+'Y(递推)'!C12,2) -> 0 | D14: =MOD('Y1'!C13+'Y(递推)'!D12,2) -> 1 | E14: =MOD('Y1'!D13+'Y(递推)'!E12,2) -> 0 | F14: =MOD('Y1'!E13+'Y(递推)'!F12,2) -> 1 | G14: =MOD('Y1'!F13+'Y(递推)'!G12,2) -> 0 | H14: =MOD('Y1'!G13+'Y(递推)'!H12,2) -> 0 | I14: =MOD('Y1'!H13+'Y(递推)'!I12,2) -> 1 | ... U14: =MOD('Y1'!T13+'Y(递推)'!U12,2) -> 0
... B22: =MOD('Y1'!A21+'Y(递推)'!B20,2) -> 0 | C22: =MOD('Y1'!B21+'Y(递推)'!C20,2) -> 0 | D22: =MOD('Y1'!C21+'Y(递推)'!D20,2) -> 1 | E22: =MOD('Y1'!D21+'Y(递推)'!E20,2) -> 0 | F22: =MOD('Y1'!E21+'Y(递推)'!F20,2) -> 0 | G22: =MOD('Y1'!F21+'Y(递推)'!G20,2) -> 1 | H22: =MOD('Y1'!G21+'Y(递推)'!H20,2) -> 1 | I22: =MOD('Y1'!H21+'Y(递推)'!I20,2) -> 1 | ... U22: =MOD('Y1'!T21+'Y(递推)'!U20,2) -> 0

Sheet K
B2: 1 | C2: =MOD(B1+B3,2) -> 0 | D2: =MOD(C1+C3,2) -> 1 | E2: =MOD(D1+D3,2) -> 0 | F2: =MOD(E1+E3,2) -> 0 | G2: =MOD(F1+F3,2) -> 0 | H2: =MOD(G1+G3,2) -> 1 | I2: =MOD(H1+H3,2) -> 0 | J2: =MOD(I1+I3,2) -> 0 | ... AG2: =MOD(AF1+AF3,2) -> 0
B3: 0 | C3: =MOD(B2+B4,2) -> 1 | D3: =MOD(C2+C4,2) -> 0 | E3: =MOD(D2+D4,2) -> 0 | F3: =MOD(E2+E4,2) -> 0 | G3: =MOD(F2+F4,2) -> 1 | H3: =MOD(G2+G4,2) -> 0 | I3: =MOD(H2+H4,2) -> 0 | J3: =MOD(I2+I4,2) -> 0 | ... AG3: =MOD(AF2+AF4,2) -> 0
B4: 0 | C4: =MOD(B3+B5,2) -> 0 | D4: =MOD(C3+C5,2) -> 1 | E4: =MOD(D3+D5,2) -> 0 | F4: =MOD(E3+E5,2) -> 1 | G4: =MOD(F3+F5,2) -> 0 | H4: =MOD(G3+G5,2) -> 1 | I4: =MOD(H3+H5,2) -> 0 | J4: =MOD(I3+I5,2) -> 0 | ... AG4: =MOD(AF3+AF5,2) -> 0
B5: 0 | C5: =MOD(B4+B6,2) -> 0 | D5: =MOD(C4+C6,2) -> 0 | E5: =MOD(D4+D6,2) -> 1 | F5: =MOD(E4+E6,2) -> 0 | G5: =MOD(F4+F6,2) -> 0 | H5: =MOD(G4+G6,2) -> 0 | I5: =MOD(H4+H6,2) -> 0 | J5: =MOD(I4+I6,2) -> 0 | ... AG5: =MOD(AF4+AF6,2) -> 0
B6: 0 | C6: =MOD(B5+B7,2) -> 0 | D6: =MOD(C5+C7,2) -> 0 | E6: =MOD(D5+D7,2) -> 0 | F6: =MOD(E5+E7,2) -> 1 | G6: =MOD(F5+F7,2) -> 0 | H6: =MOD(G5+G7,2) -> 1 | I6: =MOD(H5+H7,2) -> 0 | J6: =MOD(I5+I7,2) -> 0 | ... AG6: =MOD(AF5+AF7,2) -> 0
B7: 0 | C7: =MOD(B6+B8,2) -> 0 | D7: =MOD(C6+C8,2) -> 0 | E7: =MOD(D6+D8,2) -> 0 | F7: =MOD(E6+E8,2) -> 0 | G7: =MOD(F6+F8,2) -> 1 | H7: =MOD(G6+G8,2) -> 0 | I7: =MOD(H6+H8,2) -> 0 | J7: =MOD(I6+I8,2) -> 0 | ... AG7: =MOD(AF6+AF8,2) -> 0
B8: 0 | C8: =MOD(B7+B9,2) -> 0 | D8: =MOD(C7+C9,2) -> 0 | E8: =MOD(D7+D9,2) -> 0 | F8: =MOD(E7+E9,2) -> 0 | G8: =MOD(F7+F9,2) -> 0 | H8: =MOD(G7+G9,2) -> 1 | I8: =MOD(H7+H9,2) -> 0 | J8: =MOD(I7+I9,2) -> 1 | ... AG8: =MOD(AF7+AF9,2) -> 0
B9: 0 | C9: =MOD(B8+B10,2) -> 0 | D9: =MOD(C8+C10,2) -> 0 | E9: =MOD(D8+D10,2) -> 0 | F9: =MOD(E8+E10,2) -> 0 | G9: =MOD(F8+F10,2) -> 0 | H9: =MOD(G8+G10,2) -> 0 | I9: =MOD(H8+H10,2) -> 1 | J9: =MOD(I8+I10,2) -> 0 | ... AG9: =MOD(AF8+AF10,2) -> 0
B10: 0 | C10: =MOD(B9+B11,2) -> 0 | D10: =MOD(C9+C11,2) -> 0 | E10: =MOD(D9+D11,2) -> 0 | F10: =MOD(E9+E11,2) -> 0 | G10: =MOD(F9+F11,2) -> 0 | H10: =MOD(G9+G11,2) -> 0 | I10: =MOD(H9+H11,2) -> 0 | J10: =MOD(I9+I11,2) -> 1 | ... AG10: =MOD(AF9+AF11,2) -> 0
B11: 0 | C11: =MOD(B10+B12,2) -> 0 | D11: =MOD(C10+C12,2) -> 0 | E11: =MOD(D10+D12,2) -> 0 | F11: =MOD(E10+E12,2) -> 0 | G11: =MOD(F10+F12,2) -> 0 | H11: =MOD(G10+G12,2) -> 0 | I11: =MOD(H10+H12,2) -> 0 | J11: =MOD(I10+I12,2) -> 0 | ... AG11: =MOD(AF10+AF12,2) -> 0
B12: 0 | C12: =MOD(B11+B13,2) -> 0 | D12: =MOD(C11+C13,2) -> 0 | E12: =MOD(D11+D13,2) -> 0 | F12: =MOD(E11+E13,2) -> 0 | G12: =MOD(F11+F13,2) -> 0 | H12: =MOD(G11+G13,2) -> 0 | I12: =MOD(H11+H13,2) -> 0 | J12: =MOD(I11+I13,2) -> 0 | ... AG12: =MOD(AF11+AF13,2) -> 0
B13: 0 | C13: =MOD(B12+B14,2) -> 0 | D13: =MOD(C12+C14,2) -> 0 | E13: =MOD(D12+D14,2) -> 0 | F13: =MOD(E12+E14,2) -> 0 | G13: =MOD(F12+F14,2) -> 0 | H13: =MOD(G12+G14,2) -> 0 | I13: =MOD(H12+H14,2) -> 0 | J13: =MOD(I12+I14,2) -> 0 | ... AG13: =MOD(AF12+AF14,2) -> 0
... B33: 0 | C33: =MOD(B32+B34,2) -> 0 | D33: =MOD(C32+C34,2) -> 0 | E33: =MOD(D32+D34,2) -> 0 | F33: =MOD(E32+E34,2) -> 0 | G33: =MOD(F32+F34,2) -> 0 | H33: =MOD(G32+G34,2) -> 0 | I33: =MOD(H32+H34,2) -> 0 | J33: =MOD(I32+I34,2) -> 0 | ... AG33: =MOD(AF32+AF34,2) -> 1

Sheet K^-1
B2: 1 | C2: =MOD(B1+A2,2) -> 0 | D2: =MOD(C1+B2,2) -> 1 | E2: =MOD(D1+C2,2) -> 0 | F2: =MOD(E1+D2,2) -> 1 | G2: =MOD(F1+E2,2) -> 0 | H2: =MOD(G1+F2,2) -> 1 | I2: =MOD(H1+G2,2) -> 0 | J2: =MOD(I1+H2,2) -> 1 | ... AG2: =MOD(AF1+AE2,2) -> 0
B3: 0 | C3: =MOD(B2+A3,2) -> 1 | D3: =MOD(C2+B3,2) -> 0 | E3: =MOD(D2+C3,2) -> 0 | F3: =MOD(E2+D3,2) -> 0 | G3: =MOD(F2+E3,2) -> 1 | H3: =MOD(G2+F3,2) -> 0 | I3: =MOD(H2+G3,2) -> 0 | J3: =MOD(I2+H3,2) -> 0 | ... AG3: =MOD(AF2+AE3,2) -> 0
B4: 0 | C4: =MOD(B3+A4,2) -> 0 | D4: =MOD(C3+B4,2) -> 1 | E4: =MOD(D3+C4,2) -> 0 | F4: =MOD(E3+D4,2) -> 1 | G4: =MOD(F3+E4,2) -> 0 | H4: =MOD(G3+F4,2) -> 0 | I4: =MOD(H3+G4,2) -> 0 | J4: =MOD(I3+H4,2) -> 0 | ... AG4: =MOD(AF3+AE4,2) -> 0
B5: 0 | C5: =MOD(B4+A5,2) -> 0 | D5: =MOD(C4+B5,2) -> 0 | E5: =MOD(D4+C5,2) -> 1 | F5: =MOD(E4+D5,2) -> 0 | G5: =MOD(F4+E5,2) -> 0 | H5: =MOD(G4+F5,2) -> 0 | I5: =MOD(H4+G5,2) -> 0 | J5: =MOD(I4+H5,2) -> 0 | ... AG5: =MOD(AF4+AE5,2) -> 0
B6: 0 | C6: =MOD(B5+A6,2) -> 0 | D6: =MOD(C5+B6,2) -> 0 | E6: =MOD(D5+C6,2) -> 0 | F6: =MOD(E5+D6,2) -> 1 | G6: =MOD(F5+E6,2) -> 0 | H6: =MOD(G5+F6,2) -> 1 | I6: =MOD(H5+G6,2) -> 0 | J6: =MOD(I5+H6,2) -> 1 | ... AG6: =MOD(AF5+AE6,2) -> 0
B7: 0 | C7: =MOD(B6+A7,2) -> 0 | D7: =MOD(C6+B7,2) -> 0 | E7: =MOD(D6+C7,2) -> 0 | F7: =MOD(E6+D7,2) -> 0 | G7: =MOD(F6+E7,2) -> 1 | H7: =MOD(G6+F7,2) -> 0 | I7: =MOD(H6+G7,2) -> 0 | J7: =MOD(I6+H7,2) -> 0 | ... AG7: =MOD(AF6+AE7,2) -> 0
B8: 0 | C8: =MOD(B7+A8,2) -> 0 | D8: =MOD(C7+B8,2) -> 0 | E8: =MOD(D7+C8,2) -> 0 | F8: =MOD(E7+D8,2) -> 0 | G8: =MOD(F7+E8,2) -> 0 | H8: =MOD(G7+F8,2) -> 1 | I8: =MOD(H7+G8,2) -> 0 | J8: =MOD(I7+H8,2) -> 1 | ... AG8: =MOD(AF7+AE8,2) -> 0
B9: 0 | C9: =MOD(B8+A9,2) -> 0 | D9: =MOD(C8+B9,2) -> 0 | E9: =MOD(D8+C9,2) -> 0 | F9: =MOD(E8+D9,2) -> 0 | G9: =MOD(F8+E9,2) -> 0 | H9: =MOD(G8+F9,2) -> 0 | I9: =MOD(H8+G9,2) -> 1 | J9: =MOD(I8+H9,2) -> 0 | ... AG9: =MOD(AF8+AE9,2) -> 0
B10: 0 | C10: =MOD(B9+A10,2) -> 0 | D10: =MOD(C9+B10,2) -> 0 | E10: =MOD(D9+C10,2) -> 0 | F10: =MOD(E9+D10,2) -> 0 | G10: =MOD(F9+E10,2) -> 0 | H10: =MOD(G9+F10,2) -> 0 | I10: =MOD(H9+G10,2) -> 0 | J10: =MOD(I9+H10,2) -> 1 | ... AG10: =MOD(AF9+AE10,2) -> 0
B11: 0 | C11: =MOD(B10+A11,2) -> 0 | D11: =MOD(C10+B11,2) -> 0 | E11: =MOD(D10+C11,2) -> 0 | F11: =MOD(E10+D11,2) -> 0 | G11: =MOD(F10+E11,2) -> 0 | H11: =MOD(G10+F11,2) -> 0 | I11: =MOD(H10+G11,2) -> 0 | J11: =MOD(I10+H11,2) -> 0 | ... AG11: =MOD(AF10+AE11,2) -> 0
B12: 0 | C12: =MOD(B11+A12,2) -> 0 | D12: =MOD(C11+B12,2) -> 0 | E12: =MOD(D11+C12,2) -> 0 | F12: =MOD(E11+D12,2) -> 0 | G12: =MOD(F11+E12,2) -> 0 | H12: =MOD(G11+F12,2) -> 0 | I12: =MOD(H11+G12,2) -> 0 | J12: =MOD(I11+H12,2) -> 0 | ... AG12: =MOD(AF11+AE12,2) -> 0
B13: 0 | C13: =MOD(B12+A13,2) -> 0 | D13: =MOD(C12+B13,2) -> 0 | E13: =MOD(D12+C13,2) -> 0 | F13: =MOD(E12+D13,2) -> 0 | G13: =MOD(F12+E13,2) -> 0 | H13: =MOD(G12+F13,2) -> 0 | I13: =MOD(H12+G13,2) -> 0 | J13: =MOD(I12+H13,2) -> 0 | ... AG13: =MOD(AF12+AE13,2) -> 0
... B33: 0 | C33: =MOD(B32+A33,2) -> 0 | D33: =MOD(C32+B33,2) -> 0 | E33: =MOD(D32+C33,2) -> 0 | F33: =MOD(E32+D33,2) -> 0 | G33: =MOD(F32+E33,2) -> 0 | H33: =MOD(G32+F33,2) -> 0 | I33: =MOD(H32+G33,2) -> 0 | J33: =MOD(I32+H33,2) -> 0 | ... AG33: =MOD(AF32+AE33,2) -> 1

Sheet K^T
B2: 1 | C2: 0 | D2: 0 | E2: 0 | F2: 0 | G2: 0 | H2: 0 | I2: 0 | J2: 0 | K2: 0 | L2: 0 | M2: 0 | N2: 0 | O2: 0 | P2: 0 | Q2: 0 | R2: 0 | S2: 0 | T2: 0 | U2: 0 | V2: 0 | W2: 0 | X2: 0 | Y2: 0 | Z2: 0 | AA2: 0 | AB2: 0 | AC2: 0 | AD2: 0 | AE2: 0 | AF2: 0 | AG2: 0
B3: =MOD(A2+C2,2) -> 0 | C3: =MOD(B2+D2,2) -> 1 | D3: =MOD(C2+E2,2) -> 0 | E3: =MOD(D2+F2,2) -> 0 | F3: =MOD(E2+G2,2) -> 0 | G3: =MOD(F2+H2,2) -> 0 | H3: =MOD(G2+I2,2) -> 0 | I3: =MOD(H2+J2,2) -> 0 | ... AG3: =MOD(AF2+AH2,2) -> 0
B4: =MOD(A3+C3,2) -> 1 | C4: =MOD(B3+D3,2) -> 0 | D4: =MOD(C3+E3,2) -> 1 | E4: =MOD(D3+F3,2) -> 0 | F4: =MOD(E3+G3,2) -> 0 | G4: =MOD(F3+H3,2) -> 0 | H4: =MOD(G3+I3,2) -> 0 | I4: =MOD(H3+J3,2) -> 0 | ... AG4: =MOD(AF3+AH3,2) -> 0
B5: =MOD(A4+C4,2) -> 0 | C5: =MOD(B4+D4,2) -> 0 | D5: =MOD(C4+E4,2) -> 0 | E5: =MOD(D4+F4,2) -> 1 | F5: =MOD(E4+G4,2) -> 0 | G5: =MOD(F4+H4,2) -> 0 | H5: =MOD(G4+I4,2) -> 0 | I5: =MOD(H4+J4,2) -> 0 | ... AG5: =MOD(AF4+AH4,2) -> 0
B6: =MOD(A5+C5,2) -> 0 | C6: =MOD(B5+D5,2) -> 0 | D6: =MOD(C5+E5,2) -> 1 | E6: =MOD(D5+F5,2) -> 0 | F6: =MOD(E5+G5,2) -> 1 | G6: =MOD(F5+H5,2) -> 0 | H6: =MOD(G5+I5,2) -> 0 | I6: =MOD(H5+J5,2) -> 0 | ... AG6: =MOD(AF5+AH5,2) -> 0
B7: =MOD(A6+C6,2) -> 0 | C7: =MOD(B6+D6,2) -> 1 | D7: =MOD(C6+E6,2) -> 0 | E7: =MOD(D6+F6,2) -> 0 | F7: =MOD(E6+G6,2) -> 0 | G7: =MOD(F6+H6,2) -> 1 | H7: =MOD(G6+I6,2) -> 0 | I7: =MOD(H6+J6,2) -> 0 | ... AG7: =MOD(AF6+AH6,2) -> 0
B8: =MOD(A7+C7,2) -> 1 | C8: =MOD(B7+D7,2) -> 0 | D8: =MOD(C7+E7,2) -> 1 | E8: =MOD(D7+F7,2) -> 0 | F8: =MOD(E7+G7,2) -> 1 | G8: =MOD(F7+H7,2) -> 0 | H8: =MOD(G7+I7,2) -> 1 | I8: =MOD(H7+J7,2) -> 0 | ... AG8: =MOD(AF7+AH7,2) -> 0
B9: =MOD(A8+C8,2) -> 0 | C9: =MOD(B8+D8,2) -> 0 | D9: =MOD(C8+E8,2) -> 0 | E9: =MOD(D8+F8,2) -> 0 | F9: =MOD(E8+G8,2) -> 0 | G9: =MOD(F8+H8,2) -> 0 | H9: =MOD(G8+I8,2) -> 0 | I9: =MOD(H8+J8,2) -> 1 | ... AG9: =MOD(AF8+AH8,2) -> 0
B10: =MOD(A9+C9,2) -> 0 | C10: =MOD(B9+D9,2) -> 0 | D10: =MOD(C9+E9,2) -> 0 | E10: =MOD(D9+F9,2) -> 0 | F10: =MOD(E9+G9,2) -> 0 | G10: =MOD(F9+H9,2) -> 0 | H10: =MOD(G9+I9,2) -> 1 | I10: =MOD(H9+J9,2) -> 0 | ... AG10: =MOD(AF9+AH9,2) -> 0
B11: =MOD(A10+C10,2) -> 0 | C11: =MOD(B10+D10,2) -> 0 | D11: =MOD(C10+E10,2) -> 0 | E11: =MOD(D10+F10,2) -> 0 | F11: =MOD(E10+G10,2) -> 0 | G11: =MOD(F10+H10,2) -> 1 | H11: =MOD(G10+I10,2) -> 0 | I11: =MOD(H10+J10,2) -> 0 | ... AG11: =MOD(AF10+AH10,2) -> 0
B12: =MOD(A11+C11,2) -> 0 | C12: =MOD(B11+D11,2) -> 0 | D12: =MOD(C11+E11,2) -> 0 | E12: =MOD(D11+F11,2) -> 0 | F12: =MOD(E11+G11,2) -> 1 | G12: =MOD(F11+H11,2) -> 0 | H12: =MOD(G11+I11,2) -> 1 | I12: =MOD(H11+J11,2) -> 0 | ... AG12: =MOD(AF11+AH11,2) -> 0
B13: =MOD(A12+C12,2) -> 0 | C13: =MOD(B12+D12,2) -> 0 | D13: =MOD(C12+E12,2) -> 0 | E13: =MOD(D12+F12,2) -> 1 | F13: =MOD(E12+G12,2) -> 0 | G13: =MOD(F12+H12,2) -> 0 | H13: =MOD(G12+I12,2) -> 0 | I13: =MOD(H12+J12,2) -> 0 | ... AG13: =MOD(AF12+AH12,2) -> 0
B14: =MOD(A13+C13,2) -> 0 | C14: =MOD(B13+D13,2) -> 0 | D14: =MOD(C13+E13,2) -> 1 | E14: =MOD(D13+F13,2) -> 0 | F14: =MOD(E13+G13,2) -> 1 | G14: =MOD(F13+H13,2) -> 0 | H14: =MOD(G13+I13,2) -> 0 | I14: =MOD(H13+J13,2) -> 0 | ... AG14: =MOD(AF13+AH13,2) -> 0
... B33: =MOD(A32+C32,2) -> 0 | C33: =MOD(B32+D32,2) -> 0 | D33: =MOD(C32+E32,2) -> 0 | E33: =MOD(D32+F32,2) -> 0 | F33: =MOD(E32+G32,2) -> 0 | G33: =MOD(F32+H32,2) -> 0 | H33: =MOD(G32+I32,2) -> 0 | I33: =MOD(H32+J32,2) -> 0 | ... AG33: =MOD(AF32+AH32,2) -> 1

Sheet F
A1: n
B2: 1 | C2: 0 | D2: 0 | E2: 0 | F2: 0 | G2: 0 | H2: 0 | I2: 0 | J2: 0 | K2: 0 | L2: 0 | M2: 0 | N2: 0 | O2: 0 | P2: 0 | Q2: 0 | R2: 0 | S2: 0 | T2: 0 | U2: 0 | V2: 0 | W2: 0 | X2: 0 | Y2: 0 | Z2: 0 | AA2: 0 | AB2: 0 | AC2: 0 | AD2: 0 | AE2: 0 | AF2: 0 | AG2: 0
B3: =MOD(A2+B1,2) -> 0 | C3: =MOD(B2+C1,2) -> 1 | D3: =MOD(C2+D1,2) -> 0 | E3: =MOD(D2+E1,2) -> 0 | F3: =MOD(E2+F1,2) -> 0 | G3: =MOD(F2+G1,2) -> 0 | H3: =MOD(G2+H1,2) -> 0 | I3: =MOD(H2+I1,2) -> 0 | ... AG3: =MOD(AF2+AG1,2) -> 0
B4: =MOD(A3+B2,2) -> 1 | C4: =MOD(B3+C2,2) -> 0 | D4: =MOD(C3+D2,2) -> 1 | E4: =MOD(D3+E2,2) -> 0 | F4: =MOD(E3+F2,2) -> 0 | G4: =MOD(F3+G2,2) -> 0 | H4: =MOD(G3+H2,2) -> 0 | I4: =MOD(H3+I2,2) -> 0 | ... AG4: =MOD(AF3+AG2,2) -> 0
B5: =MOD(A4+B3,2) -> 0 | C5: =MOD(B4+C3,2) -> 0 | D5: =MOD(C4+D3,2) -> 0 | E5: =MOD(D4+E3,2) -> 1 | F5: =MOD(E4+F3,2) -> 0 | G5: =MOD(F4+G3,2) -> 0 | H5: =MOD(G4+H3,2) -> 0 | I5: =MOD(H4+I3,2) -> 0 | ... AG5: =MOD(AF4+AG3,2) -> 0
B6: =MOD(A5+B4,2) -> 1 | C6: =MOD(B5+C4,2) -> 0 | D6: =MOD(C5+D4,2) -> 1 | E6: =MOD(D5+E4,2) -> 0 | F6: =MOD(E5+F4,2) -> 1 | G6: =MOD(F5+G4,2) -> 0 | H6: =MOD(G5+H4,2) -> 0 | I6: =MOD(H5+I4,2) -> 0 | ... AG6: =MOD(AF5+AG4,2) -> 0
B7: =MOD(A6+B5,2) -> 0 | C7: =MOD(B6+C5,2) -> 1 | D7: =MOD(C6+D5,2) -> 0 | E7: =MOD(D6+E5,2) -> 0 | F7: =MOD(E6+F5,2) -> 0 | G7: =MOD(F6+G5,2) -> 1 | H7: =MOD(G6+H5,2) -> 0 | I7: =MOD(H6+I5,2) -> 0 | ... AG7: =MOD(AF6+AG5,2) -> 0
B8: =MOD(A7+B6,2) -> 1 | C8: =MOD(B7+C6,2) -> 0 | D8: =MOD(C7+D6,2) -> 0 | E8: =MOD(D7+E6,2) -> 0 | F8: =MOD(E7+F6,2) -> 1 | G8: =MOD(F7+G6,2) -> 0 | H8: =MOD(G7+H6,2) -> 1 | I8: =MOD(H7+I6,2) -> 0 | ... AG8: =MOD(AF7+AG6,2) -> 0
B9: =MOD(A8+B7,2) -> 0 | C9: =MOD(B8+C7,2) -> 0 | D9: =MOD(C8+D7,2) -> 0 | E9: =MOD(D8+E7,2) -> 0 | F9: =MOD(E8+F7,2) -> 0 | G9: =MOD(F8+G7,2) -> 0 | H9: =MOD(G8+H7,2) -> 0 | I9: =MOD(H8+I7,2) -> 1 | ... AG9: =MOD(AF8+AG7,2) -> 0
B10: =MOD(A9+B8,2) -> 1 | C10: =MOD(B9+C8,2) -> 0 | D10: =MOD(C9+D8,2) -> 0 | E10: =MOD(D9+E8,2) -> 0 | F10: =MOD(E9+F8,2) -> 1 | G10: =MOD(F9+G8,2) -> 0 | H10: =MOD(G9+H8,2) -> 1 | I10: =MOD(H9+I8,2) -> 0 | ... AG10: =MOD(AF9+AG8,2) -> 0
B11: =MOD(A10+B9,2) -> 0 | C11: =MOD(B10+C9,2) -> 1 | D11: =MOD(C10+D9,2) -> 0 | E11: =MOD(D10+E9,2) -> 0 | F11: =MOD(E10+F9,2) -> 0 | G11: =MOD(F10+G9,2) -> 1 | H11: =MOD(G10+H9,2) -> 0 | I11: =MOD(H10+I9,2) -> 0 | ... AG11: =MOD(AF10+AG9,2) -> 0
B12: =MOD(A11+B10,2) -> 1 | C12: =MOD(B11+C10,2) -> 0 | D12: =MOD(C11+D10,2) -> 1 | E12: =MOD(D11+E10,2) -> 0 | F12: =MOD(E11+F10,2) -> 1 | G12: =MOD(F11+G10,2) -> 0 | H12: =MOD(G11+H10,2) -> 0 | I12: =MOD(H11+I10,2) -> 0 | ... AG12: =MOD(AF11+AG10,2) -> 0
B13: =MOD(A12+B11,2) -> 0 | C13: =MOD(B12+C11,2) -> 0 | D13: =MOD(C12+D11,2) -> 0 | E13: =MOD(D12+E11,2) -> 1 | F13: =MOD(E12+F11,2) -> 0 | G13: =MOD(F12+G11,2) -> 0 | H13: =MOD(G12+H11,2) -> 0 | I13: =MOD(H12+I11,2) -> 0 | ... AG13: =MOD(AF12+AG11,2) -> 0
B14: =MOD(A13+B12,2) -> 1 | C14: =MOD(B13+C12,2) -> 0 | D14: =MOD(C13+D12,2) -> 1 | E14: =MOD(D13+E12,2) -> 0 | F14: =MOD(E13+F12,2) -> 0 | G14: =MOD(F13+G12,2) -> 0 | H14: =MOD(G13+H12,2) -> 0 | I14: =MOD(H13+I12,2) -> 0 | ... AG14: =MOD(AF13+AG12,2) -> 0
... B33: =MOD(A32+B31,2) -> 0 | C33: =MOD(B32+C31,2) -> 0 | D33: =MOD(C32+D31,2) -> 0 | E33: =MOD(D32+E31,2) -> 0 | F33: =MOD(E32+F31,2) -> 0 | G33: =MOD(F32+G31,2) -> 0 | H33: =MOD(G32+H31,2) -> 0 | I33: =MOD(H32+I31,2) -> 0 | ... AG33: =MOD(AF32+AG31,2) -> 1

Sheet C
A1: n
B2: 1 | C2: 0 | D2: 0 | E2: 0 | F2: 0 | G2: 0 | H2: 0 | I2: 0 | J2: 0 | K2: 0 | L2: 0 | M2: 0 | N2: 0 | O2: 0 | P2: 0 | Q2: 0 | R2: 0 | S2: 0 | T2: 0 | U2: 0 | V2: 0 | W2: 0 | X2: 0 | Y2: 0 | Z2: 0 | AA2: 0 | AB2: 0 | AC2: 0 | AD2: 0 | AE2: 0 | AF2: 0 | AG2: 0
B3: =MOD(B2+A2+B1,2) -> 1 | C3: =MOD(C2+B2+C1,2) -> 1 | D3: =MOD(D2+C2+D1,2) -> 0 | E3: =MOD(E2+D2+E1,2) -> 0 | F3: =MOD(F2+E2+F1,2) -> 0 | G3: =MOD(G2+F2+G1,2) -> 0 | H3: =MOD(H2+G2+H1,2) -> 0 | I3: =MOD(I2+H2+I1,2) -> 0 | ... AG3: =MOD(AG2+AF2+AG1,2) -> 0
B4: =MOD(B3+A3+B2,2) -> 0 | C4: =MOD(C3+B3+C2,2) -> 0 | D4: =MOD(D3+C3+D2,2) -> 1 | E4: =MOD(E3+D3+E2,2) -> 0 | F4: =MOD(F3+E3+F2,2) -> 0 | G4: =MOD(G3+F3+G2,2) -> 0 | H4: =MOD(H3+G3+H2,2) -> 0 | I4: =MOD(I3+H3+I2,2) -> 0 | ... AG4: =MOD(AG3+AF3+AG2,2) -> 0
B5: =MOD(B4+A4+B3,2) -> 1 | C5: =MOD(C4+B4+C3,2) -> 1 | D5: =MOD(D4+C4+D3,2) -> 1 | E5: =MOD(E4+D4+E3,2) -> 1 | F5: =MOD(F4+E4+F3,2) -> 0 | G5: =MOD(G4+F4+G3,2) -> 0 | H5: =MOD(H4+G4+H3,2) -> 0 | I5: =MOD(I4+H4+I3,2) -> 0 | ... AG5: =MOD(AG4+AF4+AG3,2) -> 0
B6: =MOD(B5+A5+B4,2) -> 1 | C6: =MOD(C5+B5+C4,2) -> 0 | D6: =MOD(D5+C5+D4,2) -> 1 | E6: =MOD(E5+D5+E4,2) -> 0 | F6: =MOD(F5+E5+F4,2) -> 1 | G6: =MOD(G5+F5+G4,2) -> 0 | H6: =MOD(H5+G5+H4,2) -> 0 | I6: =MOD(I5+H5+I4,2) -> 0 | ... AG6: =MOD(AG5+AF5+AG4,2) -> 0
B7: =MOD(B6+A6+B5,2) -> 0 | C7: =MOD(C6+B6+C5,2) -> 0 | D7: =MOD(D6+C6+D5,2) -> 0 | E7: =MOD(E6+D6+E5,2) -> 0 | F7: =MOD(F6+E6+F5,2) -> 1 | G7: =MOD(G6+F6+G5,2) -> 1 | H7: =MOD(H6+G6+H5,2) -> 0 | I7: =MOD(I6+H6+I5,2) -> 0 | ... AG7: =MOD(AG6+AF6+AG5,2) -> 0
